Workbook

Sheet 160刮
A1: =IF(INT(RAND()*2),CHAR(INT(RAND()*(91-65)+65)),CHAR(INT(RAND()*(58-48)+48)))&IF(INT(RAND()*2),CHAR(INT(RAND()*(91-65)+65)),CHAR(INT(RAND()*(58-48)+48)))&IF(INT(RAND()*2),CHAR(INT(RAND()*(91-65)+65)),CHAR(INT(RAND()*(58-48)+48)))&IF(INT(RAND()*2),CHAR(INT(RAND()*(91-65)+65)),CHAR(INT(RAND()*(58-48)+48)))&IF(INT(RAND()*2),CHAR(INT(RAND()*(91-65)+65)),CHAR(INT(RAND()*(58-48)+48)))&IF(INT(RAND()*2),CHAR(INT(RAND()*(91-65)+65)),CHAR(INT(RAND()*(58-48)+48)))&IF(INT(RAND()*2),CHAR(INT(RAND()*(91-65)+65)),CHAR(INT(RAND()*(58-48)+48)))&IF(INT(RAND()*2),CHAR(INT(RAND()*(91-65)+65)),CHAR(INT(RAND()*(58-48)+48)))&IF(INT(RAND()*2),CHAR(INT(RAND()*(91-65)+65)),CHAR(INT(RAND()*(58-48)+48)))&IF(INT(RAND()*2),CHAR(INT(RAND()*(91-65)+65)),CHAR(INT(RAND()*(58-48)+48))) -> QT7Q2V4E16 | B1: 萌欣國際刮卡 (一)夾出 樣，贈送 刮，對中號碼即算中獎。 (二)請勿先刮、多刮，作弊者刮中一律不算。 (三)活動為額外加贈，非屬選物販賣機之消費。 (四)活動主辦方保有最終解釋權力。 | N1: 萌欣國際刮卡 (一)夾出 樣，贈送 刮，對中號碼即算中獎。 (二)請勿先刮、多刮，作弊者刮中一律不算。 (三)活動為額外加贈，非屬選物販賣機之消費。 (四)活動主辦方保有最終解釋權力。
G2: =A1 -> QT7Q2V4E16 | H2: 第一版 | I2: 160刮 | S2: =A1 -> QT7Q2V4E16 | T2: 第二版 | U2: 160刮
B3: {=隨機產生號碼!D1:D8} -> 71 | C3: {=隨機產生號碼!D9:D16} -> 123 | D3: {=隨機產生號碼!D17:D24} -> 38 | E3: {=隨機產生號碼!D25:D32} -> 155 | F3: {=隨機產生號碼!D33:D40} -> 81 | G3: {=隨機產生號碼!D41:D48} -> 69 | H3: {=隨機產生號碼!D49:D56} -> 39 | I3: {=隨機產生號碼!D57:D64} -> 11 | J3: {=隨機產生號碼!D65:D72} -> 107 | K3: {=隨機產生號碼!D73:D80} -> 127 | N3: {=隨機產生號碼!D81:D88} -> 78 | O3: {=隨機產生號碼!D89:D96} -> 47 | P3: {=隨機產生號碼!D97:D104} -> 145 | Q3: {=隨機產生號碼!D105:D112} -> 74 | R3: {=隨機產生號碼!D113:D120} -> 59 | S3: {=隨機產生號碼!D121:D128} -> 110 | T3: {=隨機產生號碼!D129:D136} -> 45 | U3: {=隨機產生號碼!D137:D144} -> 16 | V3: {=隨機產生號碼!D145:D152} -> 2 | W3: {=隨機產生號碼!D153:D160} -> 21
B4: 112 | C4: 99 | D4: 34 | E4: 43 | F4: 64 | G4: 116 | H4: 17 | I4: 60 | J4: 4 | K4: 149 | N4: 111 | O4: 7 | P4: 5 | Q4: 97 | R4: 15 | S4: 158 | T4: 27 | U4: 13 | V4: 136 | W4: 135
B5: 66 | C5: 115 | D5: 9 | E5: 76 | F5: 117 | G5: 63 | H5: 65 | I5: 55 | J5: 54 | K5: 32 | N5: 36 | O5: 125 | P5: 84 | Q5: 10 | R5: 129 | S5: 1 | T5: 46 | U5: 79 | V5: 18 | W5: 42
B6: 92 | C6: 100 | D6: 131 | E6: 126 | F6: 72 | G6: 86 | H6: 40 | I6: 77 | J6: 114 | K6: 160 | N6: 88 | O6: 119 | P6: 144 | Q6: 29 | R6: 133 | S6: 120 | T6: 44 | U6: 12 | V6: 33 | W6: 51
B7: 87 | C7: 82 | D7: 98 | E7: 48 | F7: 68 | G7: 124 | H7: 132 | I7: 105 | J7: 108 | K7: 146 | N7: 25 | O7: 147 | P7: 104 | Q7: 121 | R7: 101 | S7: 89 | T7: 151 | U7: 67 | V7: 153 | W7: 152
B8: 20 | C8: 80 | D8: 41 | E8: 28 | F8: 95 | G8: 70 | H8: 159 | I8: 148 | J8: 49 | K8: 22 | N8: 93 | O8: 96 | P8: 118 | Q8: 19 | R8: 137 | S8: 157 | T8: 122 | U8: 53 | V8: 3 | W8: 62
B9: 35 | C9: 57 | D9: 83 | E9: 138 | F9: 37 | G9: 90 | H9: 103 | I9: 140 | J9: 73 | K9: 102 | N9: 30 | O9: 61 | P9: 50 | Q9: 113 | R9: 154 | S9: 56 | T9: 128 | U9: 23 | V9: 26 | W9: 106
B10: 94 | C10: 8 | D10: 150 | E10: 91 | F10: 141 | G10: 14 | H10: 75 | I10: 130 | J10: 156 | K10: 142 | N10: 6 | O10: 143 | P10: 58 | Q10: 52 | R10: 24 | S10: 31 | T10: 109 | U10: 134 | V10: 139 | W10: 85

Sheet 20刮
A1: =IF(INT(RAND()*2),CHAR(INT(RAND()*(91-65)+65)),CHAR(INT(RAND()*(58-48)+48)))&IF(INT(RAND()*2),CHAR(INT(RAND()*(91-65)+65)),CHAR(INT(RAND()*(58-48)+48)))&IF(INT(RAND()*2),CHAR(INT(RAND()*(91-65)+65)),CHAR(INT(RAND()*(58-48)+48)))&IF(INT(RAND()*2),CHAR(INT(RAND()*(91-65)+65)),CHAR(INT(RAND()*(58-48)+48)))&IF(INT(RAND()*2),CHAR(INT(RAND()*(91-65)+65)),CHAR(INT(RAND()*(58-48)+48)))&IF(INT(RAND()*2),CHAR(INT(RAND()*(91-65)+65)),CHAR(INT(RAND()*(58-48)+48)))&IF(INT(RAND()*2),CHAR(INT(RAND()*(91-65)+65)),CHAR(INT(RAND()*(58-48)+48)))&IF(INT(RAND()*2),CHAR(INT(RAND()*(91-65)+65)),CHAR(INT(RAND()*(58-48)+48)))&IF(INT(RAND()*2),CHAR(INT(RAND()*(91-65)+65)),CHAR(INT(RAND()*(58-48)+48)))&IF(INT(RAND()*2),CHAR(INT(RAND()*(91-65)+65)),CHAR(INT(RAND()*(58-48)+48))) -> 8PR1O1595H | B1: 萌欣國際刮卡 (一)夾出 樣，贈送 刮，對中號碼即算中獎。 (二)請勿先刮、多刮，作弊者刮中一律不算。 (三)活動為額外加贈，非屬選物販賣機之消費。 (四)活動主辦方保有最終解釋權力。 | G1: 20刮
B3: =隨機產生號碼!F1 -> 16 | D3: =隨機產生號碼!F5 -> 14 | F3: =隨機產生號碼!F9 -> 8 | H3: =隨機產生號碼!F13 -> 20 | J3: =隨機產生號碼!F17 -> 7
B5: =隨機產生號碼!F2 -> 17 | D5: =隨機產生號碼!F6 -> 4 | F5: =隨機產生號碼!F10 -> 3 | H5: =隨機產生號碼!F14 -> 13 | J5: =隨機產生號碼!F18 -> 5
B7: =隨機產生號碼!F3 -> 10 | D7: =隨機產生號碼!F7 -> 19 | F7: =隨機產生號碼!F11 -> 11 | H7: =隨機產生號碼!F15 -> 18 | J7: =隨機產生號碼!F19 -> 9
B9: =隨機產生號碼!F4 -> 2 | D9: =隨機產生號碼!F8 -> 15 | F9: =隨機產生號碼!F12 -> 1 | H9: =隨機產生號碼!F16 -> 12 | J9: =隨機產生號碼!F20 -> 6

Sheet 40刮
A1: =IF(INT(RAND()*2),CHAR(INT(RAND()*(91-65)+65)),CHAR(INT(RAND()*(58-48)+48)))&IF(INT(RAND()*2),CHAR(INT(RAND()*(91-65)+65)),CHAR(INT(RAND()*(58-48)+48)))&IF(INT(RAND()*2),CHAR(INT(RAND()*(91-65)+65)),CHAR(INT(RAND()*(58-48)+48)))&IF(INT(RAND()*2),CHAR(INT(RAND()*(91-65)+65)),CHAR(INT(RAND()*(58-48)+48)))&IF(INT(RAND()*2),CHAR(INT(RAND()*(91-65)+65)),CHAR(INT(RAND()*(58-48)+48)))&IF(INT(RAND()*2),CHAR(INT(RAND()*(91-65)+65)),CHAR(INT(RAND()*(58-48)+48)))&IF(INT(RAND()*2),CHAR(INT(RAND()*(91-65)+65)),CHAR(INT(RAND()*(58-48)+48)))&IF(INT(RAND()*2),CHAR(INT(RAND()*(91-65)+65)),CHAR(INT(RAND()*(58-48)+48)))&IF(INT(RAND()*2),CHAR(INT(RAND()*(91-65)+65)),CHAR(INT(RAND()*(58-48)+48)))&IF(INT(RAND()*2),CHAR(INT(RAND()*(91-65)+65)),CHAR(INT(RAND()*(58-48)+48))) -> 71K5EK6OX8 | B1: 萌欣國際刮卡 (一)夾出 樣，贈送 刮，對中號碼即算中獎。 (二)請勿先刮、多刮，作弊者刮中一律不算。 (三)活動為額外加贈，非屬選物販賣機之消費。 (四)活動主辦方保有最終解釋權力。
F3: 40刮
B4: {=隨機產生號碼!H1:H5} -> 33 | C4: {=隨機產生號碼!H6:H10} -> 10 | D4: {=隨機產生號碼!H11:H15} -> 11 | E4: {=隨機產生號碼!H16:H20} -> 8 | F4: {=隨機產生號碼!H21:H25} -> 18 | G4: {=隨機產生號碼!H26:H30} -> 30 | H4: {=隨機產生號碼!H31:H35} -> 13 | I4: {=隨機產生號碼!H36:H40} -> 4
B5: 35 | C5: 21 | D5: 37 | E5: 2 | F5: 12 | G5: 5 | H5: 34 | I5: 17
B6: 32 | C6: 20 | D6: 25 | E6: 15 | F6: 26 | G6: 40 | H6: 29 | I6: 24
B7: 31 | C7: 23 | D7: 3 | E7: 38 | F7: 27 | G7: 1 | H7: 36 | I7: 39
B8: 7 | C8: 16 | D8: 19 | E8: 9 | F8: 22 | G8: 28 | H8: 6 | I8: 14

Sheet 60刮
A1: =IF(INT(RAND()*2),CHAR(INT(RAND()*(91-65)+65)),CHAR(INT(RAND()*(58-48)+48)))&IF(INT(RAND()*2),CHAR(INT(RAND()*(91-65)+65)),CHAR(INT(RAND()*(58-48)+48)))&IF(INT(RAND()*2),CHAR(INT(RAND()*(91-65)+65)),CHAR(INT(RAND()*(58-48)+48)))&IF(INT(RAND()*2),CHAR(INT(RAND()*(91-65)+65)),CHAR(INT(RAND()*(58-48)+48)))&IF(INT(RAND()*2),CHAR(INT(RAND()*(91-65)+65)),CHAR(INT(RAND()*(58-48)+48)))&IF(INT(RAND()*2),CHAR(INT(RAND()*(91-65)+65)),CHAR(INT(RAND()*(58-48)+48)))&IF(INT(RAND()*2),CHAR(INT(RAND()*(91-65)+65)),CHAR(INT(RAND()*(58-48)+48)))&IF(INT(RAND()*2),CHAR(INT(RAND()*(91-65)+65)),CHAR(INT(RAND()*(58-48)+48)))&IF(INT(RAND()*2),CHAR(INT(RAND()*(91-65)+65)),CHAR(INT(RAND()*(58-48)+48)))&IF(INT(RAND()*2),CHAR(INT(RAND()*(91-65)+65)),CHAR(INT(RAND()*(58-48)+48))) -> USEZMAUK46 | B1: 萌欣國際刮卡 (一)夾出 樣，贈送 刮，對中號碼即算中獎。 (二)請勿先刮、多刮，作弊者刮中一律不算。 (三)活動為額外加贈，非屬選物販賣機之消費。 (四)活動主辦方保有最終解釋權力。 | G1: 60刮
B4: {=隨機產生號碼!J1:J6} -> 48 | C4: {=隨機產生號碼!J7:J12} -> 11 | D4: {=隨機產生號碼!J13:J18} -> 44 | E4: {=隨機產生號碼!J19:J24} -> 19 | F4: {=隨機產生號碼!J25:J30} -> 51 | G4: {=隨機產生號碼!J31:J36} -> 45 | H4: {=隨機產生號碼!J37:J42} -> 17 | I4: {=隨機產生號碼!J43:J48} -> 43 | J4: {=隨機產生號碼!J49:J54} -> 39 | K4: {=隨機產生號碼!J55:J60} -> 34
B5: 30 | C5: 8 | D5: 33 | E5: 32 | F5: 41 | G5: 59 | H5: 2 | I5: 20 | J5: 14 | K5: 28
B6: 13 | C6: 49 | D6: 53 | E6: 36 | F6: 40 | G6: 46 | H6: 42 | I6: 9 | J6: 24 | K6: 29
B7: 1 | C7: 23 | D7: 27 | E7: 37 | F7: 60 | G7: 50 | H7: 31 | I7: 7 | J7: 6 | K7: 22
B8: 18 | C8: 35 | D8: 15 | E8: 3 | F8: 56 | G8: 12 | H8: 16 | I8: 55 | J8: 57 | K8: 52
B9: 10 | C9: 26 | D9: 25 | E9: 5 | F9: 38 | G9: 54 | H9: 58 | I9: 21 | J9: 4 | K9: 47

Sheet 120刮
A1: =IF(INT(RAND()*2),CHAR(INT(RAND()*(91-65)+65)),CHAR(INT(RAND()*(58-48)+48)))&IF(INT(RAND()*2),CHAR(INT(RAND()*(91-65)+65)),CHAR(INT(RAND()*(58-48)+48)))&IF(INT(RAND()*2),CHAR(INT(RAND()*(91-65)+65)),CHAR(INT(RAND()*(58-48)+48)))&IF(INT(RAND()*2),CHAR(INT(RAND()*(91-65)+65)),CHAR(INT(RAND()*(58-48)+48)))&IF(INT(RAND()*2),CHAR(INT(RAND()*(91-65)+65)),CHAR(INT(RAND()*(58-48)+48)))&IF(INT(RAND()*2),CHAR(INT(RAND()*(91-65)+65)),CHAR(INT(RAND()*(58-48)+48)))&IF(INT(RAND()*2),CHAR(INT(RAND()*(91-65)+65)),CHAR(INT(RAND()*(58-48)+48)))&IF(INT(RAND()*2),CHAR(INT(RAND()*(91-65)+65)),CHAR(INT(RAND()*(58-48)+48)))&IF(INT(RAND()*2),CHAR(INT(RAND()*(91-65)+65)),CHAR(INT(RAND()*(58-48)+48)))&IF(INT(RAND()*2),CHAR(INT(RAND()*(91-65)+65)),CHAR(INT(RAND()*(58-48)+48))) -> L8Z34P3234 | B1: 萌欣國際刮卡 | E1: (一)夾出 樣，贈送 刮，對中號碼即算中獎。 (二)請勿先刮、多刮，作弊者刮中一律不算。 (三)活動為額外加贈，非屬選物販賣機之消費。 (四)活動主辦方保有最終解釋權力。 | K1: 120刮
B3: {=隨機產生號碼!$L1:$L10} -> 92 | C3: {=隨機產生號碼!$L11:$L20} -> 83 | D3: {=隨機產生號碼!$L21:$L30} -> 23 | E3: {=隨機產生號碼!$L31:$L40} -> 5 | F3: {=隨機產生號碼!$L41:$L50} -> 76 | G3: {=隨機產生號碼!$L51:$L60} -> 45 | H3: {=隨機產生號碼!$L61:$L70} -> 24 | I3: {=隨機產生號碼!$L71:$L80} -> 14 | J3: {=隨機產生號碼!$L81:$L90} -> 63 | K3: {=隨機產生號碼!$L91:$L100} -> 106 | L3: {=隨機產生號碼!$L101:$L110} -> 67 | M3: {=隨機產生號碼!$L111:$L120} -> 39
B4: 7 | C4: 80 | D4: 36 | E4: 60 | F4: 41 | G4: 8 | H4: 46 | I4: 2 | J4: 88 | K4: 1 | L4: 112 | M4: 35
B5: 74 | C5: 16 | D5: 13 | E5: 42 | F5: 27 | G5: 55 | H5: 87 | I5: 31 | J5: 114 | K5: 68 | L5: 21 | M5: 82
B6: 18 | C6: 117 | D6: 71 | E6: 62 | F6: 20 | G6: 105 | H6: 34 | I6: 100 | J6: 49 | K6: 64 | L6: 40 | M6: 115
B7: 94 | C7: 32 | D7: 72 | E7: 3 | F7: 12 | G7: 119 | H7: 77 | I7: 66 | J7: 118 | K7: 99 | L7: 93 | M7: 89
B8: 37 | C8: 70 | D8: 73 | E8: 43 | F8: 17 | G8: 38 | H8: 19 | I8: 107 | J8: 51 | K8: 109 | L8: 108 | M8: 103
B9: 120 | C9: 59 | D9: 33 | E9: 52 | F9: 104 | G9: 101 | H9: 65 | I9: 4 | J9: 25 | K9: 15 | L9: 86 | M9: 22
B10: 30 | C10: 75 | D10: 81 | E10: 6 | F10: 98 | G10: 84 | H10: 116 | I10: 113 | J10: 11 | K10: 97 | L10: 69 | M10: 54
B11: 28 | C11: 9 | D11: 10 | E11: 56 | F11: 44 | G11: 110 | H11: 29 | I11: 111 | J11: 95 | K11: 91 | L11: 53 | M11: 58
B12: 57 | C12: 50 | D12: 61 | E12: 26 | F12: 48 | G12: 78 | H12: 79 | I12: 90 | J12: 85 | K12: 47 | L12: 96 | M12: 102

Sheet 100刮
A1: =IF(INT(RAND()*2),CHAR(INT(RAND()*(91-65)+65)),CHAR(INT(RAND()*(58-48)+48)))&IF(INT(RAND()*2),CHAR(INT(RAND()*(91-65)+65)),CHAR(INT(RAND()*(58-48)+48)))&IF(INT(RAND()*2),CHAR(INT(RAND()*(91-65)+65)),CHAR(INT(RAND()*(58-48)+48)))&IF(INT(RAND()*2),CHAR(INT(RAND()*(91-65)+65)),CHAR(INT(RAND()*(58-48)+48)))&IF(INT(RAND()*2),CHAR(INT(RAND()*(91-65)+65)),CHAR(INT(RAND()*(58-48)+48)))&IF(INT(RAND()*2),CHAR(INT(RAND()*(91-65)+65)),CHAR(INT(RAND()*(58-48)+48)))&IF(INT(RAND()*2),CHAR(INT(RAND()*(91-65)+65)),CHAR(INT(RAND()*(58-48)+48)))&IF(INT(RAND()*2),CHAR(INT(RAND()*(91-65)+65)),CHAR(INT(RAND()*(58-48)+48)))&IF(INT(RAND()*2),CHAR(INT(RAND()*(91-65)+65)),CHAR(INT(RAND()*(58-48)+48)))&IF(INT(RAND()*2),CHAR(INT(RAND()*(91-65)+65)),CHAR(INT(RAND()*(58-48)+48))) -> 146119DF73 | B1: (一)夾出 樣，贈送 刮，對中號碼即算中獎。 (二)請勿先刮、多刮，作弊者刮中一律不算。 (三)活動為額外加贈，非屬選物販賣機之消費。 (四)活動主辦方保有最終解釋權力。 | E1: 萌欣國際刮卡 | I1: 100刮
B3: {=隨機產生號碼!N1:N10} -> 16 | C3: {=隨機產生號碼!N11:N20} -> 81 | D3: {=隨機產生號碼!N21:N30} -> 97 | E3: {=隨機產生號碼!N31:N40} -> 19 | F3: {=隨機產生號碼!N41:N50} -> 89 | G3: {=隨機產生號碼!N51:N60} -> 94 | H3: {=隨機產生號碼!N61:N70} -> 40 | I3: {=隨機產生號碼!N71:N80} -> 64 | J3: {=隨機產生號碼!N81:N90} -> 2 | K3: {=隨機產生號碼!N91:N100} -> 82
B4: 98 | C4: 85 | D4: 31 | E4: 29 | F4: 54 | G4: 68 | H4: 15 | I4: 46 | J4: 61 | K4: 20
B5: 33 | C5: 25 | D5: 38 | E5: 10 | F5: 90 | G5: 78 | H5: 72 | I5: 17 | J5: 66 | K5: 11
B6: 24 | C6: 62 | D6: 5 | E6: 6 | F6: 39 | G6: 58 | H6: 65 | I6: 59 | J6: 44 | K6: 70
B7: 49 | C7: 88 | D7: 84 | E7: 3 | F7: 76 | G7: 23 | H7: 8 | I7: 48 | J7: 63 | K7: 77
B8: 13 | C8: 4 | D8: 9 | E8: 83 | F8: 53 | G8: 22 | H8: 86 | I8: 26 | J8: 32 | K8: 67
B9: 99 | C9: 100 | D9: 96 | E9: 92 | F9: 57 | G9: 91 | H9: 28 | I9: 42 | J9: 79 | K9: 1
B10: 45 | C10: 75 | D10: 30 | E10: 34 | F10: 50 | G10: 74 | H10: 41 | I10: 36 | J10: 18 | K10: 7
B11: 43 | C11: 37 | D11: 12 | E11: 60 | F11: 87 | G11: 51 | H11: 21 | I11: 52 | J11: 71 | K11: 69
B12: 47 | C12: 14 | D12: 73 | E12: 56 | F12: 55 | G12: 93 | H12: 27 | I12: 35 | J12: 80 | K12: 95

Sheet 80刮
A1: =IF(INT(RAND()*2),CHAR(INT(RAND()*(91-65)+65)),CHAR(INT(RAND()*(58-48)+48)))&IF(INT(RAND()*2),CHAR(INT(RAND()*(91-65)+65)),CHAR(INT(RAND()*(58-48)+48)))&IF(INT(RAND()*2),CHAR(INT(RAND()*(91-65)+65)),CHAR(INT(RAND()*(58-48)+48)))&IF(INT(RAND()*2),CHAR(INT(RAND()*(91-65)+65)),CHAR(INT(RAND()*(58-48)+48)))&IF(INT(RAND()*2),CHAR(INT(RAND()*(91-65)+65)),CHAR(INT(RAND()*(58-48)+48)))&IF(INT(RAND()*2),CHAR(INT(RAND()*(91-65)+65)),CHAR(INT(RAND()*(58-48)+48)))&IF(INT(RAND()*2),CHAR(INT(RAND()*(91-65)+65)),CHAR(INT(RAND()*(58-48)+48)))&IF(INT(RAND()*2),CHAR(INT(RAND()*(91-65)+65)),CHAR(INT(RAND()*(58-48)+48)))&IF(INT(RAND()*2),CHAR(INT(RAND()*(91-65)+65)),CHAR(INT(RAND()*(58-48)+48)))&IF(INT(RAND()*2),CHAR(INT(RAND()*(91-65)+65)),CHAR(INT(RAND()*(58-48)+48))) -> T76HV32063 | B1: 萌欣國際刮卡 (一)夾出 樣，贈送 刮，對中號碼即算中獎。 (二)請勿先刮、多刮，作弊者刮中一律不算。 (三)活動為額外加贈，非屬選物販賣機之消費。 (四)活動主辦方保有最終解釋權力。 | G1: 80刮
B3: {=隨機產生號碼!B1:B8} -> 7 | C3: {=隨機產生號碼!B9:B16} -> 74 | D3: {=隨機產生號碼!B17:B24} -> 27 | E3: {=隨機產生號碼!B25:B32} -> 76 | F3: {=隨機產生號碼!B33:B40} -> 59 | G3: {=隨機產生號碼!B41:B48} -> 80 | H3: {=隨機產生號碼!B49:B56} -> 4 | I3: {=隨機產生號碼!B57:B64} -> 20 | J3: {=隨機產生號碼!B65:B72} -> 69 | K3: {=隨機產生號碼!B73:B80} -> 70
B4: 1 | C4: 23 | D4: 3 | E4: 51 | F4: 58 | G4: 49 | H4: 54 | I4: 41 | J4: 63 | K4: 77
B5: 46 | C5: 37 | D5: 26 | E5: 10 | F5: 19 | G5: 6 | H5: 53 | I5: 68 | J5: 66 | K5: 31
B6: 5 | C6: 64 | D6: 67 | E6: 16 | F6: 65 | G6: 45 | H6: 22 | I6: 8 | J6: 33 | K6: 30
B7: 18 | C7: 48 | D7: 2 | E7: 9 | F7: 61 | G7: 25 | H7: 72 | I7: 55 | J7: 78 | K7: 13
B8: 57 | C8: 36 | D8: 14 | E8: 62 | F8: 34 | G8: 75 | H8: 29 | I8: 47 | J8: 39 | K8: 17
B9: 21 | C9: 15 | D9: 79 | E9: 73 | F9: 32 | G9: 40 | H9: 50 | I9: 35 | J9: 24 | K9: 42
B10: 11 | C10: 44 | D10: 38 | E10: 28 | F10: 56 | G10: 43 | H10: 71 | I10: 60 | J10: 12 | K10: 52

Sheet 隨機產生號碼
A1: =RAND() -> 0.87630379 | B1: =RANK(A1,$A$1:$A$80) -> 7 | C1: =RAND() -> 0.55119805 | D1: =RANK(C1,$C$1:$C$160) -> 71 | E1: =RAND() -> 0.36502073 | F1: =RANK(E1,E1:E20) -> 16 | G1: =RAND() -> 0.19442484 | H1: =RANK(G1,$G$1:$G$40) -> 33 | I1: =RAND() -> 0.17067807 | J1: =RANK(I1,$I$1:$I$60) -> 48 | K1: =RAND() -> 0.21886219 | L1: =RANK(K1,$K$1:$K$120) -> 92 | M1: =RAND() -> 0.83691998 | N1: =RANK(M1,$M$1:$M$100) -> 16
A2: =RAND() -> 0.98203365 | B2: =RANK(A2,$A$1:$A$80) -> 1 | C2: =RAND() -> 0.3397919 | D2: =RANK(C2,$C$1:$C$160) -> 112 | E2: =RAND() -> 0.35410064 | F2: =RANK(E2,$E$1:$E$20) -> 17 | G2: =RAND() -> 0.16526257 | H2: =RANK(G2,$G$1:$G$40) -> 35 | I2: =RAND() -> 0.49609475 | J2: =RANK(I2,$I$1:$I$60) -> 30 | K2: =RAND() -> 0.96713064 | L2: =RANK(K2,$K$1:$K$120) -> 7 | M2: =RAND() -> 0.024084037 | N2: =RANK(M2,$M$1:$M$100) -> 98
A3: =RAND() -> 0.39497215 | B3: =RANK(A3,$A$1:$A$80) -> 46 | C3: =RAND() -> 0.57704755 | D3: =RANK(C3,$C$1:$C$160) -> 66 | E3: =RAND() -> 0.67453897 | F3: =RANK(E3,$E$1:$E$20) -> 10 | G3: =RAND() -> 0.34414557 | H3: =RANK(G3,$G$1:$G$40) -> 32 | I3: =RAND() -> 0.86581731 | J3: =RANK(I3,$I$1:$I$60) -> 13 | K3: =RAND() -> 0.38918072 | L3: =RANK(K3,$K$1:$K$120) -> 74 | M3: =RAND() -> 0.64579281 | N3: =RANK(M3,$M$1:$M$100) -> 33
A4: =RAND() -> 0.92047039 | B4: =RANK(A4,$A$1:$A$80) -> 5 | C4: =RAND() -> 0.44750382 | D4: =RANK(C4,$C$1:$C$160) -> 92 | E4: =RAND() -> 0.96460785 | F4: =RANK(E4,$E$1:$E$20) -> 2 | G4: =RAND() -> 0.35407459 | H4: =RANK(G4,$G$1:$G$40) -> 31 | I4: =RAND() -> 0.99551147 | J4: =RANK(I4,$I$1:$I$60) -> 1 | K4: =RAND() -> 0.84642102 | L4: =RANK(K4,$K$1:$K$120) -> 18 | M4: =RAND() -> 0.71947705 | N4: =RANK(M4,$M$1:$M$100) -> 24
A5: =RAND() -> 0.71902755 | B5: =RANK(A5,$A$1:$A$80) -> 18 | C5: =RAND() -> 0.48172722 | D5: =RANK(C5,$C$1:$C$160) -> 87 | E5: =RAND() -> 0.44598114 | F5: =RANK(E5,$E$1:$E$20) -> 14 | G5: =RAND() -> 0.82829841 | H5: =RANK(G5,$G$1:$G$40) -> 7 | I5: =RAND() -> 0.76383189 | J5: =RANK(I5,$I$1:$I$60) -> 18 | K5: =RAND() -> 0.19047228 | L5: =RANK(K5,$K$1:$K$120) -> 94 | M5: =RAND() -> 0.5040088 | N5: =RANK(M5,$M$1:$M$100) -> 49
A6: =RAND() -> 0.27189627 | B6: =RANK(A6,$A$1:$A$80) -> 57 | C6: =RAND() -> 0.88303377 | D6: =RANK(C6,$C$1:$C$160) -> 20 | E6: =RAND() -> 0.87085796 | F6: =RANK(E6,$E$1:$E$20) -> 4 | G6: =RAND() -> 0.78609351 | H6: =RANK(G6,$G$1:$G$40) -> 10 | I6: =RAND() -> 0.90827718 | J6: =RANK(I6,$I$1:$I$60) -> 10 | K6: =RAND() -> 0.71461668 | L6: =RANK(K6,$K$1:$K$120) -> 37 | M6: =RAND() -> 0.85746214 | N6: =RANK(M6,$M$1:$M$100) -> 13
A7: =RAND() -> 0.69309293 | B7: =RANK(A7,$A$1:$A$80) -> 21 | C7: =RAND() -> 0.76022165 | D7: =RANK(C7,$C$1:$C$160) -> 35 | E7: =RAND() -> 0.11850093 | F7: =RANK(E7,$E$1:$E$20) -> 19 | G7: =RAND() -> 0.50977422 | H7: =RANK(G7,$G$1:$G$40) -> 21 | I7: =RAND() -> 0.90539832 | J7: =RANK(I7,$I$1:$I$60) -> 11 | K7: =RAND() -> 0.003557235 | L7: =RANK(K7,$K$1:$K$120) -> 120 | M7: =RAND() -> 0.022854264 | N7: =RANK(M7,$M$1:$M$100) -> 99
A8: =RAND() -> 0.85471312 | B8: =RANK(A8,$A$1:$A$80) -> 11 | C8: =RAND() -> 0.44093212 | D8: =RANK(C8,$C$1:$C$160) -> 94 | E8: =RAND() -> 0.39458452 | F8: =RANK(E8,$E$1:$E$20) -> 15 | G8: =RAND() -> 0.52342672 | H8: =RANK(G8,$G$1:$G$40) -> 20 | I8: =RAND() -> 0.91860015 | J8: =RANK(I8,$I$1:$I$60) -> 8 | K8: =RAND() -> 0.7517506 | L8: =RANK(K8,$K$1:$K$120) -> 30 | M8: =RAND() -> 0.57519854 | N8: =RANK(M8,$M$1:$M$100) -> 45
A9: =RAND() -> 0.053627701 | B9: =RANK(A9,$A$1:$A$80) -> 74 | C9: =RAND() -> 0.27916315 | D9: =RANK(C9,$C$1:$C$160) -> 123 | E9: =RAND() -> 0.71136252 | F9: =RANK(E9,$E$1:$E$20) -> 8 | G9: =RAND() -> 0.48415739 | H9: =RANK(G9,$G$1:$G$40) -> 23 | I9: =RAND() -> 0.15478887 | J9: =RANK(I9,$I$1:$I$60) -> 49 | K9: =RAND() -> 0.75285942 | L9: =RANK(K9,$K$1:$K$120) -> 28 | M9: =RAND() -> 0.59218999 | N9: =RANK(M9,$M$1:$M$100) -> 43
A10: =RAND() -> 0.67390183 | B10: =RANK(A10,$A$1:$A$80) -> 23 | C10: =RAND() -> 0.4188505 | D10: =RANK(C10,$C$1:$C$160) -> 99 | E10: =RAND() -> 0.90264416 | F10: =RANK(E10,$E$1:$E$20) -> 3 | G10: =RAND() -> 0.58366521 | H10: =RANK(G10,$G$1:$G$40) -> 16 | I10: =RAND() -> 0.62624523 | J10: =RANK(I10,$I$1:$I$60) -> 23 | K10: =RAND() -> 0.51082189 | L10: =RANK(K10,$K$1:$K$120) -> 57 | M10: =RAND() -> 0.5305766 | N10: =RANK(M10,$M$1:$M$100) -> 47
A11: =RAND() -> 0.49304166 | B11: =RANK(A11,$A$1:$A$80) -> 37 | C11: =RAND() -> 0.32970032 | D11: =RANK(C11,$C$1:$C$160) -> 115 | E11: =RAND() -> 0.65855625 | F11: =RANK(E11,$E$1:$E$20) -> 11 | G11: =RAND() -> 0.75970625 | H11: =RANK(G11,$G$1:$G$40) -> 11 | I11: =RAND() -> 0.42647356 | J11: =RANK(I11,$I$1:$I$60) -> 35 | K11: =RAND() -> 0.31522419 | L11: =RANK(K11,$K$1:$K$120) -> 83 | M11: =RAND() -> 0.227034 | N11: =RANK(M11,$M$1:$M$100) -> 81
A12: =RAND() -> 0.15640452 | B12: =RANK(A12,$A$1:$A$80) -> 64 | C12: =RAND() -> 0.39133583 | D12: =RANK(C12,$C$1:$C$160) -> 100 | E12: =RAND() -> 0.97403487 | F12: =RANK(E12,$E$1:$E$20) -> 1 | G12: =RAND() -> 0.15062042 | H12: =RANK(G12,$G$1:$G$40) -> 37 | I12: =RAND() -> 0.56668727 | J12: =RANK(I12,$I$1:$I$60) -> 26 | K12: =RAND() -> 0.32401821 | L12: =RANK(K12,$K$1:$K$120) -> 80 | M12: =RAND() -> 0.18555797 | N12: =RANK(M12,$M$1:$M$100) -> 85
A13: =RAND() -> 0.35819234 | B13: =RANK(A13,$A$1:$A$80) -> 48 | C13: =RAND() -> 0.50593804 | D13: =RANK(C13,$C$1:$C$160) -> 82 | E13: =RAND() -> 0.022453105 | F13: =RANK(E13,$E$1:$E$20) -> 20 | G13: =RAND() -> 0.46620388 | H13: =RANK(G13,$G$1:$G$40) -> 25 | I13: =RAND() -> 0.28645047 | J13: =RANK(I13,$I$1:$I$60) -> 44 | K13: =RAND() -> 0.86778985 | L13: =RANK(K13,$K$1:$K$120) -> 16 | M13: =RAND() -> 0.71497984 | N13: =RANK(M13,$M$1:$M$100) -> 25
... A20: =RAND() -> 0.138706 | B20: =RANK(A20,$A$1:$A$80) -> 67 | C20: =RAND() -> 0.21125549 | D20: =RANK(C20,$C$1:$C$160) -> 131 | E20: =RAND() -> 0.74982872 | F20: =RANK(E20,$E$1:$E$20) -> 6 | G20: =RAND() -> 0.79607134 | H20: =RANK(G20,$G$1:$G$40) -> 9 | I20: =RAND() -> 0.46189845 | J20: =RANK(I20,$I$1:$I$60) -> 32 | K20: =RAND() -> 0.59957139 | L20: =RANK(K20,$K$1:$K$120) -> 50 | M20: =RAND() -> 0.85329237 | N20: =RANK(M20,$M$1:$M$100) -> 14
A21: =RAND() -> 0.96106512 | B21: =RANK(A21,$A$1:$A$80) -> 2 | C21: =RAND() -> 0.42257346 | D21: =RANK(C21,$C$1:$C$160) -> 98 | G21: =RAND() -> 0.57367211 | H21: =RANK(G21,$G$1:$G$40) -> 18 | I21: =RAND() -> 0.42382487 | J21: =RANK(I21,$I$1:$I$60) -> 36 | K21: =RAND() -> 0.80445724 | L21: =RANK(K21,$K$1:$K$120) -> 23 | M21: =RAND() -> 0.038346878 | N21: =RANK(M21,$M$1:$M$100) -> 97
A22: =RAND() -> 0.80873349 | B22: =RANK(A22,$A$1:$A$80) -> 14 | C22: =RAND() -> 0.7333404 | D22: =RANK(C22,$C$1:$C$160) -> 41 | G22: =RAND() -> 0.74946337 | H22: =RANK(G22,$G$1:$G$40) -> 12 | I22: =RAND() -> 0.41382121 | J22: =RANK(I22,$I$1:$I$60) -> 37 | K22: =RAND() -> 0.71793921 | L22: =RANK(K22,$K$1:$K$120) -> 36 | M22: =RAND() -> 0.66259022 | N22: =RANK(M22,$M$1:$M$100) -> 31
A23: =RAND() -> 0.0068900247 | B23: =RANK(A23,$A$1:$A$80) -> 79 | C23: =RAND() -> 0.50237997 | D23: =RANK(C23,$C$1:$C$160) -> 83 | G23: =RAND() -> 0.45731648 | H23: =RANK(G23,$G$1:$G$40) -> 26 | I23: =RAND() -> 0.99201073 | J23: =RANK(I23,$I$1:$I$60) -> 3 | K23: =RAND() -> 0.89436108 | L23: =RANK(K23,$K$1:$K$120) -> 13 | M23: =RAND() -> 0.62009425 | N23: =RANK(M23,$M$1:$M$100) -> 38
A24: =RAND() -> 0.48243997 | B24: =RANK(A24,$A$1:$A$80) -> 38 | C24: =RAND() -> 0.10817795 | D24: =RANK(C24,$C$1:$C$160) -> 150 | G24: =RAND() -> 0.44786764 | H24: =RANK(G24,$G$1:$G$40) -> 27 | I24: =RAND() -> 0.96198071 | J24: =RANK(I24,$I$1:$I$60) -> 5 | K24: =RAND() -> 0.40462186 | L24: =RANK(K24,$K$1:$K$120) -> 71 | M24: =RAND() -> 0.94836624 | N24: =RANK(M24,$M$1:$M$100) -> 5
A25: =RAND() -> 0.022505915 | B25: =RANK(A25,$A$1:$A$80) -> 76 | C25: =RAND() -> 0.060807246 | D25: =RANK(C25,$C$1:$C$160) -> 155 | G25: =RAND() -> 0.48607585 | H25: =RANK(G25,$G$1:$G$40) -> 22 | I25: =RAND() -> 0.11816481 | J25: =RANK(I25,$I$1:$I$60) -> 51 | K25: =RAND() -> 0.39230519 | L25: =RANK(K25,$K$1:$K$120) -> 72 | M25: =RAND() -> 0.19037975 | N25: =RANK(M25,$M$1:$M$100) -> 84
A26: =RAND() -> 0.30226981 | B26: =RANK(A26,$A$1:$A$80) -> 51 | C26: =RAND() -> 0.71922778 | D26: =RANK(C26,$C$1:$C$160) -> 43 | G26: =RAND() -> 0.36720013 | H26: =RANK(G26,$G$1:$G$40) -> 30 | I26: =RAND() -> 0.32819258 | J26: =RANK(I26,$I$1:$I$60) -> 41 | K26: =RAND() -> 0.39123865 | L26: =RANK(K26,$K$1:$K$120) -> 73 | M26: =RAND() -> 0.89446201 | N26: =RANK(M26,$M$1:$M$100) -> 9
A27: =RAND() -> 0.86177888 | B27: =RANK(A27,$A$1:$A$80) -> 10 | C27: =RAND() -> 0.53361085 | D27: =RANK(C27,$C$1:$C$160) -> 76 | G27: =RAND() -> 0.87499355 | H27: =RANK(G27,$G$1:$G$40) -> 5 | I27: =RAND() -> 0.35994981 | J27: =RANK(I27,$I$1:$I$60) -> 40 | K27: =RAND() -> 0.72861265 | L27: =RANK(K27,$K$1:$K$120) -> 33 | M27: =RAND() -> 0.053573051 | N27: =RANK(M27,$M$1:$M$100) -> 96
A28: =RAND() -> 0.746256 | B28: =RANK(A28,$A$1:$A$80) -> 16 | C28: =RAND() -> 0.24054694 | D28: =RANK(C28,$C$1:$C$160) -> 126 | G28: =RAND() -> 0.013126066 | H28: =RANK(G28,$G$1:$G$40) -> 40 | I28: =RAND() -> 0.0059806787 | J28: =RANK(I28,$I$1:$I$60) -> 60 | K28: =RAND() -> 0.32131095 | L28: =RANK(K28,$K$1:$K$120) -> 81 | M28: =RAND() -> 0.67368842 | N28: =RANK(M28,$M$1:$M$100) -> 30
A29: =RAND() -> 0.8630072 | B29: =RANK(A29,$A$1:$A$80) -> 9 | C29: =RAND() -> 0.70401711 | D29: =RANK(C29,$C$1:$C$160) -> 48 | G29: =RAND() -> 0.98315813 | H29: =RANK(G29,$G$1:$G$40) -> 1 | I29: =RAND() -> 0.096347902 | J29: =RANK(I29,$I$1:$I$60) -> 56 | K29: =RAND() -> 0.90922777 | L29: =RANK(K29,$K$1:$K$120) -> 10 | M29: =RAND() -> 0.88234777 | N29: =RANK(M29,$M$1:$M$100) -> 12
A30: =RAND() -> 0.19939132 | B30: =RANK(A30,$A$1:$A$80) -> 62 | C30: =RAND() -> 0.80825206 | D30: =RANK(C30,$C$1:$C$160) -> 28 | G30: =RAND() -> 0.40408262 | H30: =RANK(G30,$G$1:$G$40) -> 28 | I30: =RAND() -> 0.38923106 | J30: =RANK(I30,$I$1:$I$60) -> 38 | K30: =RAND() -> 0.48109663 | L30: =RANK(K30,$K$1:$K$120) -> 61 | M30: =RAND() -> 0.3298865 | N30: =RANK(M30,$M$1:$M$100) -> 73
A31: =RAND() -> 0.064070574 | B31: =RANK(A31,$A$1:$A$80) -> 73 | C31: =RAND() -> 0.17246636 | D31: =RANK(C31,$C$1:$C$160) -> 138 | G31: =RAND() -> 0.69360767 | H31: =RANK(G31,$G$1:$G$40) -> 13 | I31: =RAND() -> 0.27619348 | J31: =RANK(I31,$I$1:$I$60) -> 45 | K31: =RAND() -> 0.97335322 | L31: =RANK(K31,$K$1:$K$120) -> 5 | M31: =RAND() -> 0.75924142 | N31: =RANK(M31,$M$1:$M$100) -> 19
A32: =RAND() -> 0.59299056 | B32: =RANK(A32,$A$1:$A$80) -> 28 | C32: =RAND() -> 0.45234913 | D32: =RANK(C32,$C$1:$C$160) -> 91 | G32: =RAND() -> 0.16643787 | H32: =RANK(G32,$G$1:$G$40) -> 34 | I32: =RAND() -> 0.067293865 | J32: =RANK(I32,$I$1:$I$60) -> 59 | K32: =RAND() -> 0.48385158 | L32: =RANK(K32,$K$1:$K$120) -> 60 | M32: =RAND() -> 0.68002406 | N32: =RANK(M32,$M$1:$M$100) -> 29
... A40: =RAND() -> 0.28003984 | B40: =RANK(A40,$A$1:$A$80) -> 56 | C40: =RAND() -> 0.15060826 | D40: =RANK(C40,$C$1:$C$160) -> 141 | G40: =RAND() -> 0.68187541 | H40: =RANK(G40,$G$1:$G$40) -> 14 | I40: =RAND() -> 0.46410364 | J40: =RANK(I40,$I$1:$I$60) -> 31 | K40: =RAND() -> 0.76840999 | L40: =RANK(K40,$K$1:$K$120) -> 26 | M40: =RAND() -> 0.44350366 | N40: =RANK(M40,$M$1:$M$100) -> 56
A41: =RAND() -> 0.0036450369 | B41: =RANK(A41,$A$1:$A$80) -> 80 | C41: =RAND() -> 0.56292245 | D41: =RANK(C41,$C$1:$C$160) -> 69 | I41: =RAND() -> 0.77360273 | J41: =RANK(I41,$I$1:$I$60) -> 16 | K41: =RAND() -> 0.34937172 | L41: =RANK(K41,$K$1:$K$120) -> 76 | M41: =RAND() -> 0.1534235 | N41: =RANK(M41,$M$1:$M$100) -> 89
A42: =RAND() -> 0.33401292 | B42: =RANK(A42,$A$1:$A$80) -> 49 | C42: =RAND() -> 0.32810503 | D42: =RANK(C42,$C$1:$C$160) -> 116 | I42: =RAND() -> 0.071120018 | J42: =RANK(I42,$I$1:$I$60) -> 58 | K42: =RAND() -> 0.70681535 | L42: =RANK(K42,$K$1:$K$120) -> 41 | M42: =RAND() -> 0.47380845 | N42: =RANK(M42,$M$1:$M$100) -> 54
A43: =RAND() -> 0.88111563 | B43: =RANK(A43,$A$1:$A$80) -> 6 | C43: =RAND() -> 0.61640703 | D43: =RANK(C43,$C$1:$C$160) -> 63 | I43: =RAND() -> 0.3055232 | J43: =RANK(I43,$I$1:$I$60) -> 43 | K43: =RAND() -> 0.76088773 | L43: =RANK(K43,$K$1:$K$120) -> 27 | M43: =RAND() -> 0.15230408 | N43: =RANK(M43,$M$1:$M$100) -> 90
A44: =RAND() -> 0.40486374 | B44: =RANK(A44,$A$1:$A$80) -> 45 | C44: =RAND() -> 0.48851195 | D44: =RANK(C44,$C$1:$C$160) -> 86 | I44: =RAND() -> 0.7260085 | J44: =RANK(I44,$I$1:$I$60) -> 20 | K44: =RAND() -> 0.81956962 | L44: =RANK(K44,$K$1:$K$120) -> 20 | M44: =RAND() -> 0.61542407 | N44: =RANK(M44,$M$1:$M$100) -> 39
A45: =RAND() -> 0.66449249 | B45: =RANK(A45,$A$1:$A$80) -> 25 | C45: =RAND() -> 0.27325889 | D45: =RANK(C45,$C$1:$C$160) -> 124 | I45: =RAND() -> 0.9177724 | J45: =RANK(I45,$I$1:$I$60) -> 9 | K45: =RAND() -> 0.89437816 | L45: =RANK(K45,$K$1:$K$120) -> 12 | M45: =RAND() -> 0.30026519 | N45: =RANK(M45,$M$1:$M$100) -> 76
A46: =RAND() -> 0.02838806 | B46: =RANK(A46,$A$1:$A$80) -> 75 | C46: =RAND() -> 0.55582012 | D46: =RANK(C46,$C$1:$C$160) -> 70 | I46: =RAND() -> 0.93477846 | J46: =RANK(I46,$I$1:$I$60) -> 7 | K46: =RAND() -> 0.85595288 | L46: =RANK(K46,$K$1:$K$120) -> 17 | M46: =RAND() -> 0.47951087 | N46: =RANK(M46,$M$1:$M$100) -> 53
A47: =RAND() -> 0.46952106 | B47: =RANK(A47,$A$1:$A$80) -> 40 | C47: =RAND() -> 0.46476694 | D47: =RANK(C47,$C$1:$C$160) -> 90 | I47: =RAND() -> 0.10353316 | J47: =RANK(I47,$I$1:$I$60) -> 55 | K47: =RAND() -> 0.10430971 | L47: =RANK(K47,$K$1:$K$120) -> 104 | M47: =RAND() -> 0.44017749 | N47: =RANK(M47,$M$1:$M$100) -> 57
A48: =RAND() -> 0.42544066 | B48: =RANK(A48,$A$1:$A$80) -> 43 | C48: =RAND() -> 0.92561889 | D48: =RANK(C48,$C$1:$C$160) -> 14 | I48: =RAND() -> 0.67742971 | J48: =RANK(I48,$I$1:$I$60) -> 21 | K48: =RAND() -> 0.16525805 | L48: =RANK(K48,$K$1:$K$120) -> 98 | M48: =RAND() -> 0.49915916 | N48: =RANK(M48,$M$1:$M$100) -> 50
A49: =RAND() -> 0.93677612 | B49: =RANK(A49,$A$1:$A$80) -> 4 | C49: =RAND() -> 0.74319769 | D49: =RANK(C49,$C$1:$C$160) -> 39 | I49: =RAND() -> 0.36735401 | J49: =RANK(I49,$I$1:$I$60) -> 39 | K49: =RAND() -> 0.64087854 | L49: =RANK(K49,$K$1:$K$120) -> 44 | M49: =RAND() -> 0.16552918 | N49: =RANK(M49,$M$1:$M$100) -> 87
A50: =RAND() -> 0.28867939 | B50: =RANK(A50,$A$1:$A$80) -> 54 | C50: =RAND() -> 0.8928517 | D50: =RANK(C50,$C$1:$C$160) -> 17 | I50: =RAND() -> 0.82190633 | J50: =RANK(I50,$I$1:$I$60) -> 14 | K50: =RAND() -> 0.62305966 | L50: =RANK(K50,$K$1:$K$120) -> 48 | M50: =RAND() -> 0.47222849 | N50: =RANK(M50,$M$1:$M$100) -> 55
A51: =RAND() -> 0.29843569 | B51: =RANK(A51,$A$1:$A$80) -> 53 | C51: =RAND() -> 0.59255839 | D51: =RANK(C51,$C$1:$C$160) -> 65 | I51: =RAND() -> 0.59059504 | J51: =RANK(I51,$I$1:$I$60) -> 24 | K51: =RAND() -> 0.63443576 | L51: =RANK(K51,$K$1:$K$120) -> 45 | M51: =RAND() -> 0.10076678 | N51: =RANK(M51,$M$1:$M$100) -> 94
A52: =RAND() -> 0.69018005 | B52: =RANK(A52,$A$1:$A$80) -> 22 | C52: =RAND() -> 0.73913633 | D52: =RANK(C52,$C$1:$C$160) -> 40 | I52: =RAND() -> 0.93727745 | J52: =RANK(I52,$I$1:$I$60) -> 6 | K52: =RAND() -> 0.95625531 | L52: =RANK(K52,$K$1:$K$120) -> 8 | M52: =RAND() -> 0.35448968 | N52: =RANK(M52,$M$1:$M$100) -> 68
... A60: =RAND() -> 0.86597681 | B60: =RANK(A60,$A$1:$A$80) -> 8 | C60: =RAND() -> 0.53036961 | D60: =RANK(C60,$C$1:$C$160) -> 77 | I60: =RAND() -> 0.18940117 | J60: =RANK(I60,$I$1:$I$60) -> 47 | K60: =RAND() -> 0.3330164 | L60: =RANK(K60,$K$1:$K$120) -> 78 | M60: =RAND() -> 0.10261263 | N60: =RANK(M60,$M$1:$M$100) -> 93
...
