Workbook

Sheet 160刮
A1: =IF(INT(RAND()*2),CHAR(INT(RAND()*(91-65)+65)),CHAR(INT(RAND()*(58-48)+48)))&IF(INT(RAND()*2),CHAR(INT(RAND()*(91-65)+65)),CHAR(INT(RAND()*(58-48)+48)))&IF(INT(RAND()*2),CHAR(INT(RAND()*(91-65)+65)),CHAR(INT(RAND()*(58-48)+48)))&IF(INT(RAND()*2),CHAR(INT(RAND()*(91-65)+65)),CHAR(INT(RAND()*(58-48)+48)))&IF(INT(RAND()*2),CHAR(INT(RAND()*(91-65)+65)),CHAR(INT(RAND()*(58-48)+48)))&IF(INT(RAND()*2),CHAR(INT(RAND()*(91-65)+65)),CHAR(INT(RAND()*(58-48)+48)))&IF(INT(RAND()*2),CHAR(INT(RAND()*(91-65)+65)),CHAR(INT(RAND()*(58-48)+48)))&IF(INT(RAND()*2),CHAR(INT(RAND()*(91-65)+65)),CHAR(INT(RAND()*(58-48)+48)))&IF(INT(RAND()*2),CHAR(INT(RAND()*(91-65)+65)),CHAR(INT(RAND()*(58-48)+48)))&IF(INT(RAND()*2),CHAR(INT(RAND()*(91-65)+65)),CHAR(INT(RAND()*(58-48)+48))) -> W60B275HWW | M1: 萌欣國際刮卡 (一)夾出 樣，贈送 刮，對中號碼即算中獎。 (二)請勿先刮、多刮，作弊者刮中一律不算。 (三)活動為額外加贈，非屬選物販賣機之消費。 (四)活動主辦方保有最終解釋權力。
E2: =A1 -> W60B275HWW | G2: 第一版 | H2: 160刮 | R2: =A1 -> W60B275HWW | S2: 第二版 | T2: 160刮
E3: =A2 | J3: 萌欣國際刮卡 (一)夾出 樣，贈送 刮，對中號碼即算中獎。 (二)請勿先刮、多刮，作弊者刮中一律不算。 (三)活動為額外加贈，非屬選物販賣機之消費。 (四)活動主辦方保有最終解釋權力。

Sheet 20刮
A1: =IF(INT(RAND()*2),CHAR(INT(RAND()*(91-65)+65)),CHAR(INT(RAND()*(58-48)+48)))&IF(INT(RAND()*2),CHAR(INT(RAND()*(91-65)+65)),CHAR(INT(RAND()*(58-48)+48)))&IF(INT(RAND()*2),CHAR(INT(RAND()*(91-65)+65)),CHAR(INT(RAND()*(58-48)+48)))&IF(INT(RAND()*2),CHAR(INT(RAND()*(91-65)+65)),CHAR(INT(RAND()*(58-48)+48)))&IF(INT(RAND()*2),CHAR(INT(RAND()*(91-65)+65)),CHAR(INT(RAND()*(58-48)+48)))&IF(INT(RAND()*2),CHAR(INT(RAND()*(91-65)+65)),CHAR(INT(RAND()*(58-48)+48)))&IF(INT(RAND()*2),CHAR(INT(RAND()*(91-65)+65)),CHAR(INT(RAND()*(58-48)+48)))&IF(INT(RAND()*2),CHAR(INT(RAND()*(91-65)+65)),CHAR(INT(RAND()*(58-48)+48)))&IF(INT(RAND()*2),CHAR(INT(RAND()*(91-65)+65)),CHAR(INT(RAND()*(58-48)+48)))&IF(INT(RAND()*2),CHAR(INT(RAND()*(91-65)+65)),CHAR(INT(RAND()*(58-48)+48))) -> 95N7Z363W3 | B1: 萌欣國際刮卡 (一)夾出 樣，贈送 刮，對中號碼即算中獎。 (二)請勿先刮、多刮，作弊者刮中一律不算。 (三)活動為額外加贈，非屬選物販賣機之消費。 (四)活動主辦方保有最終解釋權力。 | G1: 20刮
B3: ='隨機產生號碼'!F1 -> 10 | D3: ='隨機產生號碼'!F5 -> 3 | F3: ='隨機產生號碼'!F9 -> 17 | H3: ='隨機產生號碼'!F13 -> 20 | J3: ='隨機產生號碼'!F17 -> 14
B5: ='隨機產生號碼'!F2 -> 12 | D5: ='隨機產生號碼'!F6 -> 9 | F5: ='隨機產生號碼'!F10 -> 15 | H5: ='隨機產生號碼'!F14 -> 7 | J5: ='隨機產生號碼'!F18 -> 11
B7: ='隨機產生號碼'!F3 -> 2 | D7: ='隨機產生號碼'!F7 -> 4 | F7: ='隨機產生號碼'!F11 -> 18 | H7: ='隨機產生號碼'!F15 -> 6 | J7: ='隨機產生號碼'!F19 -> 1
B9: ='隨機產生號碼'!F4 -> 5 | D9: ='隨機產生號碼'!F8 -> 8 | F9: ='隨機產生號碼'!F12 -> 19 | H9: ='隨機產生號碼'!F16 -> 16 | J9: ='隨機產生號碼'!F20 -> 13

Sheet 40刮
A1: =IF(INT(RAND()*2),CHAR(INT(RAND()*(91-65)+65)),CHAR(INT(RAND()*(58-48)+48)))&IF(INT(RAND()*2),CHAR(INT(RAND()*(91-65)+65)),CHAR(INT(RAND()*(58-48)+48)))&IF(INT(RAND()*2),CHAR(INT(RAND()*(91-65)+65)),CHAR(INT(RAND()*(58-48)+48)))&IF(INT(RAND()*2),CHAR(INT(RAND()*(91-65)+65)),CHAR(INT(RAND()*(58-48)+48)))&IF(INT(RAND()*2),CHAR(INT(RAND()*(91-65)+65)),CHAR(INT(RAND()*(58-48)+48)))&IF(INT(RAND()*2),CHAR(INT(RAND()*(91-65)+65)),CHAR(INT(RAND()*(58-48)+48)))&IF(INT(RAND()*2),CHAR(INT(RAND()*(91-65)+65)),CHAR(INT(RAND()*(58-48)+48)))&IF(INT(RAND()*2),CHAR(INT(RAND()*(91-65)+65)),CHAR(INT(RAND()*(58-48)+48)))&IF(INT(RAND()*2),CHAR(INT(RAND()*(91-65)+65)),CHAR(INT(RAND()*(58-48)+48)))&IF(INT(RAND()*2),CHAR(INT(RAND()*(91-65)+65)),CHAR(INT(RAND()*(58-48)+48))) -> 14AHK9UR7N | B1: 萌欣國際刮卡 (一)夾出 樣，贈送 刮，對中號碼即算中獎。 (二)請勿先刮、多刮，作弊者刮中一律不算。 (三)活動為額外加贈，非屬選物販賣機之消費。 (四)活動主辦方保有最終解釋權力。
F3: 40刮
B4: {='隨機產生號碼'!H1:H5} -> 16 | C4: {='隨機產生號碼'!H6:H10} -> 37 | D4: {='隨機產生號碼'!H11:H15} -> 26 | E4: {='隨機產生號碼'!H16:H20} -> 7 | F4: {='隨機產生號碼'!H21:H25} -> 10 | G4: {='隨機產生號碼'!H26:H30} -> 13 | H4: {='隨機產生號碼'!H31:H35} -> 6 | I4: {='隨機產生號碼'!H36:H40} -> 23
B5: 5 | C5: 2 | D5: 31 | E5: 25 | F5: 3 | G5: 1 | H5: 12 | I5: 18
B6: 11 | C6: 30 | D6: 35 | E6: 15 | F6: 14 | G6: 27 | H6: 32 | I6: 19
B7: 4 | C7: 40 | D7: 9 | E7: 39 | F7: 24 | G7: 8 | H7: 28 | I7: 17
B8: 34 | C8: 33 | D8: 29 | E8: 20 | F8: 38 | G8: 22 | H8: 36 | I8: 21

Sheet 60刮
A1: =IF(INT(RAND()*2),CHAR(INT(RAND()*(91-65)+65)),CHAR(INT(RAND()*(58-48)+48)))&IF(INT(RAND()*2),CHAR(INT(RAND()*(91-65)+65)),CHAR(INT(RAND()*(58-48)+48)))&IF(INT(RAND()*2),CHAR(INT(RAND()*(91-65)+65)),CHAR(INT(RAND()*(58-48)+48)))&IF(INT(RAND()*2),CHAR(INT(RAND()*(91-65)+65)),CHAR(INT(RAND()*(58-48)+48)))&IF(INT(RAND()*2),CHAR(INT(RAND()*(91-65)+65)),CHAR(INT(RAND()*(58-48)+48)))&IF(INT(RAND()*2),CHAR(INT(RAND()*(91-65)+65)),CHAR(INT(RAND()*(58-48)+48)))&IF(INT(RAND()*2),CHAR(INT(RAND()*(91-65)+65)),CHAR(INT(RAND()*(58-48)+48)))&IF(INT(RAND()*2),CHAR(INT(RAND()*(91-65)+65)),CHAR(INT(RAND()*(58-48)+48)))&IF(INT(RAND()*2),CHAR(INT(RAND()*(91-65)+65)),CHAR(INT(RAND()*(58-48)+48)))&IF(INT(RAND()*2),CHAR(INT(RAND()*(91-65)+65)),CHAR(INT(RAND()*(58-48)+48))) -> VR6YVXC855 | B1: 萌欣國際刮卡 (一)夾出 樣，贈送 刮，對中號碼即算中獎。 (二)請勿先刮、多刮，作弊者刮中一律不算。 (三)活動為額外加贈，非屬選物販賣機之消費。 (四)活動主辦方保有最終解釋權力。 | G1: 60刮
B4: {='隨機產生號碼'!J1:J6} -> 55 | C4: {='隨機產生號碼'!J7:J12} -> 34 | D4: {='隨機產生號碼'!J13:J18} -> 23 | E4: {='隨機產生號碼'!J19:J24} -> 1 | F4: {='隨機產生號碼'!J25:J30} -> 45 | G4: {='隨機產生號碼'!J31:J36} -> 36 | H4: {='隨機產生號碼'!J37:J42} -> 19 | I4: {='隨機產生號碼'!J43:J48} -> 25 | J4: {='隨機產生號碼'!J49:J54} -> 27 | K4: {='隨機產生號碼'!J55:J60} -> 14
B5: 10 | C5: 9 | D5: 21 | E5: 38 | F5: 35 | G5: 4 | H5: 46 | I5: 16 | J5: 48 | K5: 56
B6: 5 | C6: 54 | D6: 17 | E6: 37 | F6: 59 | G6: 52 | H6: 33 | I6: 44 | J6: 2 | K6: 8
B7: 11 | C7: 41 | D7: 29 | E7: 47 | F7: 24 | G7: 40 | H7: 6 | I7: 13 | J7: 31 | K7: 22
B8: 28 | C8: 50 | D8: 18 | E8: 42 | F8: 58 | G8: 7 | H8: 60 | I8: 39 | J8: 20 | K8: 26
B9: 30 | C9: 3 | D9: 53 | E9: 15 | F9: 32 | G9: 12 | H9: 57 | I9: 49 | J9: 51 | K9: 43

Sheet 120刮
A1: =IF(INT(RAND()*2),CHAR(INT(RAND()*(91-65)+65)),CHAR(INT(RAND()*(58-48)+48)))&IF(INT(RAND()*2),CHAR(INT(RAND()*(91-65)+65)),CHAR(INT(RAND()*(58-48)+48)))&IF(INT(RAND()*2),CHAR(INT(RAND()*(91-65)+65)),CHAR(INT(RAND()*(58-48)+48)))&IF(INT(RAND()*2),CHAR(INT(RAND()*(91-65)+65)),CHAR(INT(RAND()*(58-48)+48)))&IF(INT(RAND()*2),CHAR(INT(RAND()*(91-65)+65)),CHAR(INT(RAND()*(58-48)+48)))&IF(INT(RAND()*2),CHAR(INT(RAND()*(91-65)+65)),CHAR(INT(RAND()*(58-48)+48)))&IF(INT(RAND()*2),CHAR(INT(RAND()*(91-65)+65)),CHAR(INT(RAND()*(58-48)+48)))&IF(INT(RAND()*2),CHAR(INT(RAND()*(91-65)+65)),CHAR(INT(RAND()*(58-48)+48)))&IF(INT(RAND()*2),CHAR(INT(RAND()*(91-65)+65)),CHAR(INT(RAND()*(58-48)+48)))&IF(INT(RAND()*2),CHAR(INT(RAND()*(91-65)+65)),CHAR(INT(RAND()*(58-48)+48))) -> X6OG1LM2ND | E1: (一)夾出 樣，贈送 刮，對中號碼即算中獎。 (二)請勿先刮、多刮，作弊者刮中一律不算。 (三)活動為額外加贈，非屬選物販賣機之消費。 (四)活動主辦方保有最終解釋權力。 | K1: 120刮
B3: {='隨機產生號碼'!$L1:$L10} -> 8 | C3: {='隨機產生號碼'!$L11:$L20} -> 117 | D3: {='隨機產生號碼'!$L21:$L30} -> 84 | E3: {='隨機產生號碼'!$L31:$L40} -> 69 | F3: {='隨機產生號碼'!$L41:$L50} -> 83 | G3: {='隨機產生號碼'!$L51:$L60} -> 66 | H3: {='隨機產生號碼'!$L61:$L70} -> 95 | I3: {='隨機產生號碼'!$L71:$L80} -> 81 | J3: {='隨機產生號碼'!$L81:$L90} -> 53 | K3: {='隨機產生號碼'!$L91:$L100} -> 54 | L3: {='隨機產生號碼'!$L101:$L110} -> 44 | M3: {='隨機產生號碼'!$L111:$L120} -> 73
B4: 75 | C4: 85 | D4: 71 | E4: 34 | F4: 99 | G4: 30 | H4: 118 | I4: 87 | J4: 42 | K4: 36 | L4: 88 | M4: 7
B5: 62 | C5: 47 | D5: 23 | E5: 13 | F5: 2 | G5: 98 | H5: 70 | I5: 33 | J5: 72 | K5: 67 | L5: 103 | M5: 31
B6: 57 | C6: 65 | D6: 4 | E6: 32 | F6: 60 | G6: 80 | H6: 39 | I6: 38 | J6: 52 | K6: 100 | L6: 1 | M6: 90
B7: 21 | C7: 3 | D7: 14 | E7: 5 | F7: 86 | G7: 116 | H7: 120 | I7: 111 | J7: 26 | K7: 51 | L7: 76 | M7: 119
B8: 104 | C8: 35 | D8: 94 | E8: 74 | F8: 102 | G8: 24 | H8: 18 | I8: 79 | J8: 12 | K8: 105 | L8: 114 | M8: 97
B9: 112 | C9: 108 | D9: 19 | E9: 109 | F9: 43 | G9: 77 | H9: 41 | I9: 11 | J9: 115 | K9: 82 | L9: 27 | M9: 61
B10: 28 | C10: 17 | D10: 6 | E10: 93 | F10: 15 | G10: 29 | H10: 16 | I10: 22 | J10: 113 | K10: 10 | L10: 45 | M10: 107
B11: 63 | C11: 68 | D11: 40 | E11: 96 | F11: 59 | G11: 48 | H11: 91 | I11: 101 | J11: 92 | K11: 20 | L11: 49 | M11: 25
B12: 89 | C12: 50 | D12: 37 | E12: 55 | F12: 9 | G12: 58 | H12: 64 | I12: 78 | J12: 106 | K12: 56 | L12: 110 | M12: 46

Sheet 100刮
A1: =IF(INT(RAND()*2),CHAR(INT(RAND()*(91-65)+65)),CHAR(INT(RAND()*(58-48)+48)))&IF(INT(RAND()*2),CHAR(INT(RAND()*(91-65)+65)),CHAR(INT(RAND()*(58-48)+48)))&IF(INT(RAND()*2),CHAR(INT(RAND()*(91-65)+65)),CHAR(INT(RAND()*(58-48)+48)))&IF(INT(RAND()*2),CHAR(INT(RAND()*(91-65)+65)),CHAR(INT(RAND()*(58-48)+48)))&IF(INT(RAND()*2),CHAR(INT(RAND()*(91-65)+65)),CHAR(INT(RAND()*(58-48)+48)))&IF(INT(RAND()*2),CHAR(INT(RAND()*(91-65)+65)),CHAR(INT(RAND()*(58-48)+48)))&IF(INT(RAND()*2),CHAR(INT(RAND()*(91-65)+65)),CHAR(INT(RAND()*(58-48)+48)))&IF(INT(RAND()*2),CHAR(INT(RAND()*(91-65)+65)),CHAR(INT(RAND()*(58-48)+48)))&IF(INT(RAND()*2),CHAR(INT(RAND()*(91-65)+65)),CHAR(INT(RAND()*(58-48)+48)))&IF(INT(RAND()*2),CHAR(INT(RAND()*(91-65)+65)),CHAR(INT(RAND()*(58-48)+48))) -> 35HDUX5Z10 | B1: (一)夾出 樣，贈送 刮，對中號碼即算中獎。 (二)請勿先刮、多刮，作弊者刮中一律不算。 (三)活動為額外加贈，非屬選物販賣機之消費。 (四)活動主辦方保有最終解釋權力。 | E1: 萌欣國際刮卡 | I1: 100刮
B3: {='隨機產生號碼'!N1:N10} -> 28 | C3: {='隨機產生號碼'!N11:N20} -> 45 | D3: {='隨機產生號碼'!N21:N30} -> 72 | E3: {='隨機產生號碼'!N31:N40} -> 51 | F3: {='隨機產生號碼'!N41:N50} -> 3 | G3: {='隨機產生號碼'!N51:N60} -> 85 | H3: {='隨機產生號碼'!N61:N70} -> 16 | I3: {='隨機產生號碼'!N71:N80} -> 20 | J3: {='隨機產生號碼'!N81:N90} -> 14 | K3: {='隨機產生號碼'!N91:N100} -> 56
B4: 38 | C4: 8 | D4: 97 | E4: 80 | F4: 40 | G4: 77 | H4: 6 | I4: 69 | J4: 74 | K4: 35
B5: 88 | C5: 49 | D5: 1 | E5: 83 | F5: 61 | G5: 84 | H5: 82 | I5: 9 | J5: 25 | K5: 5
B6: 94 | C6: 93 | D6: 73 | E6: 95 | F6: 27 | G6: 41 | H6: 79 | I6: 90 | J6: 33 | K6: 36
B7: 23 | C7: 24 | D7: 13 | E7: 58 | F7: 70 | G7: 44 | H7: 10 | I7: 71 | J7: 96 | K7: 62
B8: 98 | C8: 43 | D8: 4 | E8: 64 | F8: 21 | G8: 52 | H8: 76 | I8: 18 | J8: 47 | K8: 65
B9: 12 | C9: 29 | D9: 11 | E9: 59 | F9: 15 | G9: 86 | H9: 92 | I9: 66 | J9: 89 | K9: 26
B10: 91 | C10: 53 | D10: 34 | E10: 55 | F10: 32 | G10: 2 | H10: 63 | I10: 54 | J10: 100 | K10: 60
B11: 39 | C11: 37 | D11: 42 | E11: 67 | F11: 46 | G11: 81 | H11: 78 | I11: 57 | J11: 19 | K11: 30
B12: 48 | C12: 87 | D12: 22 | E12: 50 | F12: 68 | G12: 99 | H12: 31 | I12: 17 | J12: 75 | K12: 7

Sheet 80刮
A1: =IF(INT(RAND()*2),CHAR(INT(RAND()*(91-65)+65)),CHAR(INT(RAND()*(58-48)+48)))&IF(INT(RAND()*2),CHAR(INT(RAND()*(91-65)+65)),CHAR(INT(RAND()*(58-48)+48)))&IF(INT(RAND()*2),CHAR(INT(RAND()*(91-65)+65)),CHAR(INT(RAND()*(58-48)+48)))&IF(INT(RAND()*2),CHAR(INT(RAND()*(91-65)+65)),CHAR(INT(RAND()*(58-48)+48)))&IF(INT(RAND()*2),CHAR(INT(RAND()*(91-65)+65)),CHAR(INT(RAND()*(58-48)+48)))&IF(INT(RAND()*2),CHAR(INT(RAND()*(91-65)+65)),CHAR(INT(RAND()*(58-48)+48)))&IF(INT(RAND()*2),CHAR(INT(RAND()*(91-65)+65)),CHAR(INT(RAND()*(58-48)+48)))&IF(INT(RAND()*2),CHAR(INT(RAND()*(91-65)+65)),CHAR(INT(RAND()*(58-48)+48)))&IF(INT(RAND()*2),CHAR(INT(RAND()*(91-65)+65)),CHAR(INT(RAND()*(58-48)+48)))&IF(INT(RAND()*2),CHAR(INT(RAND()*(91-65)+65)),CHAR(INT(RAND()*(58-48)+48))) -> V7D6K4PCGE | B1: 萌欣國際刮卡 (一)夾出 樣，贈送 刮，對中號碼即算中獎。 (二)請勿先刮、多刮，作弊者刮中一律不算。 (三)活動為額外加贈，非屬選物販賣機之消費。 (四)活動主辦方保有最終解釋權力。 | G1: 80刮
B3: {='隨機產生號碼'!B1:B8} -> 47 | C3: {='隨機產生號碼'!B9:B16} -> 19 | D3: {='隨機產生號碼'!B17:B24} -> 25 | E3: {='隨機產生號碼'!B25:B32} -> 38 | F3: {='隨機產生號碼'!B33:B40} -> 17 | G3: {='隨機產生號碼'!B41:B48} -> 62 | H3: {='隨機產生號碼'!B49:B56} -> 31 | I3: {='隨機產生號碼'!B57:B64} -> 71 | J3: {='隨機產生號碼'!B65:B72} -> 26 | K3: {='隨機產生號碼'!B73:B80} -> 27
B4: 46 | C4: 49 | D4: 10 | E4: 29 | F4: 70 | G4: 50 | H4: 51 | I4: 35 | J4: 67 | K4: 28
B5: 33 | C5: 65 | D5: 13 | E5: 23 | F5: 44 | G5: 30 | H5: 40 | I5: 68 | J5: 24 | K5: 9
B6: 8 | C6: 66 | D6: 64 | E6: 77 | F6: 15 | G6: 56 | H6: 43 | I6: 5 | J6: 41 | K6: 2
B7: 54 | C7: 79 | D7: 59 | E7: 76 | F7: 72 | G7: 61 | H7: 1 | I7: 6 | J7: 53 | K7: 52
B8: 39 | C8: 45 | D8: 36 | E8: 74 | F8: 18 | G8: 48 | H8: 58 | I8: 34 | J8: 57 | K8: 63
B9: 20 | C9: 42 | D9: 22 | E9: 7 | F9: 32 | G9: 73 | H9: 80 | I9: 11 | J9: 37 | K9: 69
B10: 16 | C10: 3 | D10: 60 | E10: 4 | F10: 55 | G10: 75 | H10: 78 | I10: 14 | J10: 12 | K10: 21

Sheet 隨機產生號碼
A1: =RAND() -> 0.41012271 | B1: =RANK(A1,$A$1:$A$80) -> 47 | C1: =RAND() -> 0.85051309 | D1: =RANK(C1,$C$1:$C$160) -> 26 | E1: =RAND() -> 0.50670698 | F1: =RANK(E1,E1:E20) -> 10 | G1: =RAND() -> 0.68230813 | H1: =RANK(G1,$G$1:$G$40) -> 16 | I1: =RAND() -> 0.054118671 | J1: =RANK(I1,$I$1:$I$60) -> 55 | K1: =RAND() -> 0.94275839 | L1: =RANK(K1,$K$1:$K$120) -> 8 | M1: =RAND() -> 0.79462483 | N1: =RANK(M1,$M$1:$M$100) -> 28
A2: =RAND() -> 0.42156352 | B2: =RANK(A2,$A$1:$A$80) -> 46 | C2: =RAND() -> 0.67324867 | D2: =RANK(C2,$C$1:$C$160) -> 52 | E2: =RAND() -> 0.40409553 | F2: =RANK(E2,$E$1:$E$20) -> 12 | G2: =RAND() -> 0.88106579 | H2: =RANK(G2,$G$1:$G$40) -> 5 | I2: =RAND() -> 0.71107748 | J2: =RANK(I2,$I$1:$I$60) -> 10 | K2: =RAND() -> 0.34219347 | L2: =RANK(K2,$K$1:$K$120) -> 75 | M2: =RAND() -> 0.73660015 | N2: =RANK(M2,$M$1:$M$100) -> 38 | O2: =RAND() -> 0.22600188 | P2: =RANK(O2,$A$1:$A$80) -> #N/A | Q2: =RAND() -> 0.28439361 | R2: =RANK(Q2,$C$1:$C$160) -> #N/A | S2: =RAND() -> 0.10842959 | T2: =RANK(S2,S2:S21) -> 16 | U2: =RAND() -> 0.91633472 | V2: =RANK(U2,$G$1:$G$40) -> #N/A | W2: =RAND() -> 0.49857885 | X2: =RANK(W2,$I$1:$I$60) -> #N/A | Y2: =RAND() -> 0.42138805 | Z2: =RANK(Y2,$K$1:$K$120) -> #N/A | AA2: =RAND() -> 0.36802613 | AB2: =RANK(AA2,$M$1:$M$100) -> #N/A
A3: =RAND() -> 0.57629206 | B3: =RANK(A3,$A$1:$A$80) -> 33 | C3: =RAND() -> 0.031479359 | D3: =RANK(C3,$C$1:$C$160) -> 156 | E3: =RAND() -> 0.90197426 | F3: =RANK(E3,$E$1:$E$20) -> 2 | G3: =RAND() -> 0.81071468 | H3: =RANK(G3,$G$1:$G$40) -> 11 | I3: =RAND() -> 0.89013592 | J3: =RANK(I3,$I$1:$I$60) -> 5 | K3: =RAND() -> 0.47843947 | L3: =RANK(K3,$K$1:$K$120) -> 62 | M3: =RAND() -> 0.20768819 | N3: =RANK(M3,$M$1:$M$100) -> 88 | O3: =RAND() -> 0.95365909 | P3: =RANK(O3,$A$1:$A$80) -> #N/A | Q3: =RAND() -> 0.41898546 | R3: =RANK(Q3,$C$1:$C$160) -> #N/A | S3: =RAND() -> 0.66985163 | T3: =RANK(S3,$E$1:$E$20) -> #N/A | U3: =RAND() -> 0.19892442 | V3: =RANK(U3,$G$1:$G$40) -> #N/A | W3: =RAND() -> 0.60585972 | X3: =RANK(W3,$I$1:$I$60) -> #N/A | Y3: =RAND() -> 0.10506253 | Z3: =RANK(Y3,$K$1:$K$120) -> #N/A | AA3: =RAND() -> 0.6032783 | AB3: =RANK(AA3,$M$1:$M$100) -> #N/A
A4: =RAND() -> 0.87921058 | B4: =RANK(A4,$A$1:$A$80) -> 8 | C4: =RAND() -> 0.88472049 | D4: =RANK(C4,$C$1:$C$160) -> 19 | E4: =RAND() -> 0.75899059 | F4: =RANK(E4,$E$1:$E$20) -> 5 | G4: =RAND() -> 0.88218466 | H4: =RANK(G4,$G$1:$G$40) -> 4 | I4: =RAND() -> 0.71062439 | J4: =RANK(I4,$I$1:$I$60) -> 11 | K4: =RAND() -> 0.51938907 | L4: =RANK(K4,$K$1:$K$120) -> 57 | M4: =RAND() -> 0.10507855 | N4: =RANK(M4,$M$1:$M$100) -> 94 | O4: =RAND() -> 0.65768487 | P4: =RANK(O4,$A$1:$A$80) -> #N/A | Q4: =RAND() -> 0.13338796 | R4: =RANK(Q4,$C$1:$C$160) -> #N/A | S4: =RAND() -> 0.11498302 | T4: =RANK(S4,$E$1:$E$20) -> #N/A | U4: =RAND() -> 0.34433895 | V4: =RANK(U4,$G$1:$G$40) -> #N/A | W4: =RAND() -> 0.014584925 | X4: =RANK(W4,$I$1:$I$60) -> #N/A | Y4: =RAND() -> 0.45413346 | Z4: =RANK(Y4,$K$1:$K$120) -> #N/A | AA4: =RAND() -> 0.72511956 | AB4: =RANK(AA4,$M$1:$M$100) -> #N/A
A5: =RAND() -> 0.32771308 | B5: =RANK(A5,$A$1:$A$80) -> 54 | C5: =RAND() -> 0.61650979 | D5: =RANK(C5,$C$1:$C$160) -> 67 | E5: =RAND() -> 0.80821829 | F5: =RANK(E5,$E$1:$E$20) -> 3 | G5: =RAND() -> 0.16074067 | H5: =RANK(G5,$G$1:$G$40) -> 34 | I5: =RAND() -> 0.49158036 | J5: =RANK(I5,$I$1:$I$60) -> 28 | K5: =RAND() -> 0.82676699 | L5: =RANK(K5,$K$1:$K$120) -> 21 | M5: =RAND() -> 0.81562509 | N5: =RANK(M5,$M$1:$M$100) -> 23 | O5: =RAND() -> 0.50860301 | P5: =RANK(O5,$A$1:$A$80) -> #N/A | Q5: =RAND() -> 0.053170095 | R5: =RANK(Q5,$C$1:$C$160) -> #N/A | S5: =RAND() -> 0.67168229 | T5: =RANK(S5,$E$1:$E$20) -> #N/A | U5: =RAND() -> 0.40716178 | V5: =RANK(U5,$G$1:$G$40) -> #N/A | W5: =RAND() -> 0.16079077 | X5: =RANK(W5,$I$1:$I$60) -> #N/A | Y5: =RAND() -> 0.65579341 | Z5: =RANK(Y5,$K$1:$K$120) -> #N/A | AA5: =RAND() -> 0.86681873 | AB5: =RANK(AA5,$M$1:$M$100) -> #N/A
A6: =RAND() -> 0.53774632 | B6: =RANK(A6,$A$1:$A$80) -> 39 | C6: =RAND() -> 0.78043014 | D6: =RANK(C6,$C$1:$C$160) -> 39 | E6: =RAND() -> 0.54912907 | F6: =RANK(E6,$E$1:$E$20) -> 9 | G6: =RAND() -> 0.11775046 | H6: =RANK(G6,$G$1:$G$40) -> 37 | I6: =RAND() -> 0.4483569 | J6: =RANK(I6,$I$1:$I$60) -> 30 | K6: =RAND() -> 0.13196009 | L6: =RANK(K6,$K$1:$K$120) -> 104 | M6: =RAND() -> 0.069282165 | N6: =RANK(M6,$M$1:$M$100) -> 98 | O6: =RAND() -> 0.33698076 | P6: =RANK(O6,$A$1:$A$80) -> #N/A | Q6: =RAND() -> 0.061303277 | R6: =RANK(Q6,$C$1:$C$160) -> #N/A | S6: =RAND() -> 0.35186304 | T6: =RANK(S6,$E$1:$E$20) -> #N/A | U6: =RAND() -> 0.58533267 | V6: =RANK(U6,$G$1:$G$40) -> #N/A | W6: =RAND() -> 0.050467948 | X6: =RANK(W6,$I$1:$I$60) -> #N/A | Y6: =RAND() -> 0.21234459 | Z6: =RANK(Y6,$K$1:$K$120) -> #N/A | AA6: =RAND() -> 0.073835358 | AB6: =RANK(AA6,$M$1:$M$100) -> #N/A
A7: =RAND() -> 0.73655272 | B7: =RANK(A7,$A$1:$A$80) -> 20 | C7: =RAND() -> 0.62707161 | D7: =RANK(C7,$C$1:$C$160) -> 65 | E7: =RAND() -> 0.80020122 | F7: =RANK(E7,$E$1:$E$20) -> 4 | G7: =RAND() -> 0.94278574 | H7: =RANK(G7,$G$1:$G$40) -> 2 | I7: =RAND() -> 0.42320124 | J7: =RANK(I7,$I$1:$I$60) -> 34 | K7: =RAND() -> 0.049985993 | L7: =RANK(K7,$K$1:$K$120) -> 112 | M7: =RAND() -> 0.9021471 | N7: =RANK(M7,$M$1:$M$100) -> 12 | O7: =RAND() -> 0.59567156 | P7: =RANK(O7,$A$1:$A$80) -> #N/A | Q7: =RAND() -> 0.82111699 | R7: =RANK(Q7,$C$1:$C$160) -> #N/A | S7: =RAND() -> 0.4836622 | T7: =RANK(S7,$E$1:$E$20) -> #N/A | U7: =RAND() -> 0.42852837 | V7: =RANK(U7,$G$1:$G$40) -> #N/A | W7: =RAND() -> 0.25950014 | X7: =RANK(W7,$I$1:$I$60) -> #N/A | Y7: =RAND() -> 0.45511064 | Z7: =RANK(Y7,$K$1:$K$120) -> #N/A | AA7: =RAND() -> 0.19771902 | AB7: =RANK(AA7,$M$1:$M$100) -> #N/A
A8: =RAND() -> 0.76542467 | B8: =RANK(A8,$A$1:$A$80) -> 16 | C8: =RAND() -> 0.57393884 | D8: =RANK(C8,$C$1:$C$160) -> 74 | E8: =RAND() -> 0.56388732 | F8: =RANK(E8,$E$1:$E$20) -> 8 | G8: =RAND() -> 0.24339353 | H8: =RANK(G8,$G$1:$G$40) -> 30 | I8: =RAND() -> 0.71406344 | J8: =RANK(I8,$I$1:$I$60) -> 9 | K8: =RAND() -> 0.75438581 | L8: =RANK(K8,$K$1:$K$120) -> 28 | M8: =RAND() -> 0.148655 | N8: =RANK(M8,$M$1:$M$100) -> 91 | O8: =RAND() -> 0.6933781 | P8: =RANK(O8,$A$1:$A$80) -> #N/A | Q8: =RAND() -> 0.323644 | R8: =RANK(Q8,$C$1:$C$160) -> #N/A | S8: =RAND() -> 0.72025264 | T8: =RANK(S8,$E$1:$E$20) -> #N/A | U8: =RAND() -> 0.40121823 | V8: =RANK(U8,$G$1:$G$40) -> #N/A | W8: =RAND() -> 0.3832879 | X8: =RANK(W8,$I$1:$I$60) -> #N/A | Y8: =RAND() -> 0.054421873 | Z8: =RANK(Y8,$K$1:$K$120) -> #N/A | AA8: =RAND() -> 0.33294412 | AB8: =RANK(AA8,$M$1:$M$100) -> #N/A
A9: =RAND() -> 0.74825594 | B9: =RANK(A9,$A$1:$A$80) -> 19 | C9: =RAND() -> 0.048284973 | D9: =RANK(C9,$C$1:$C$160) -> 154 | E9: =RAND() -> 0.12720371 | F9: =RANK(E9,$E$1:$E$20) -> 17 | G9: =RAND() -> 0.043219704 | H9: =RANK(G9,$G$1:$G$40) -> 40 | I9: =RAND() -> 0.063010751 | J9: =RANK(I9,$I$1:$I$60) -> 54 | K9: =RAND() -> 0.46873691 | L9: =RANK(K9,$K$1:$K$120) -> 63 | M9: =RAND() -> 0.73443147 | N9: =RANK(M9,$M$1:$M$100) -> 39 | O9: =RAND() -> 0.96454217 | P9: =RANK(O9,$A$1:$A$80) -> #N/A | Q9: =RAND() -> 0.56360258 | R9: =RANK(Q9,$C$1:$C$160) -> #N/A | S9: =RAND() -> 0.092788507 | T9: =RANK(S9,$E$1:$E$20) -> #N/A | U9: =RAND() -> 0.95581038 | V9: =RANK(U9,$G$1:$G$40) -> #N/A | W9: =RAND() -> 0.21470427 | X9: =RANK(W9,$I$1:$I$60) -> #N/A | Y9: =RAND() -> 0.89882902 | Z9: =RANK(Y9,$K$1:$K$120) -> #N/A | AA9: =RAND() -> 0.025109681 | AB9: =RANK(AA9,$M$1:$M$100) -> #N/A
A10: =RAND() -> 0.37308874 | B10: =RANK(A10,$A$1:$A$80) -> 49 | C10: =RAND() -> 0.37962735 | D10: =RANK(C10,$C$1:$C$160) -> 101 | E10: =RAND() -> 0.16927857 | F10: =RANK(E10,$E$1:$E$20) -> 15 | G10: =RAND() -> 0.19975474 | H10: =RANK(G10,$G$1:$G$40) -> 33 | I10: =RAND() -> 0.27251884 | J10: =RANK(I10,$I$1:$I$60) -> 41 | K10: =RAND() -> 0.23339724 | L10: =RANK(K10,$K$1:$K$120) -> 89 | M10: =RAND() -> 0.61152694 | N10: =RANK(M10,$M$1:$M$100) -> 48 | O10: =RAND() -> 0.32645587 | P10: =RANK(O10,$A$1:$A$80) -> #N/A | Q10: =RAND() -> 0.47161385 | R10: =RANK(Q10,$C$1:$C$160) -> #N/A | S10: =RAND() -> 0.022296405 | T10: =RANK(S10,$E$1:$E$20) -> #N/A | U10: =RAND() -> 0.48317847 | V10: =RANK(U10,$G$1:$G$40) -> #N/A | W10: =RAND() -> 0.052952996 | X10: =RANK(W10,$I$1:$I$60) -> #N/A | Y10: =RAND() -> 0.2352331 | Z10: =RANK(Y10,$K$1:$K$120) -> #N/A | AA10: =RAND() -> 0.07531928 | AB10: =RANK(AA10,$M$1:$M$100) -> #N/A
A11: =RAND() -> 0.19061262 | B11: =RANK(A11,$A$1:$A$80) -> 65 | C11: =RAND() -> 0.91604179 | D11: =RANK(C11,$C$1:$C$160) -> 15 | E11: =RAND() -> 0.11120134 | F11: =RANK(E11,$E$1:$E$20) -> 18 | G11: =RAND() -> 0.42022746 | H11: =RANK(G11,$G$1:$G$40) -> 26 | I11: =RAND() -> 0.13889302 | J11: =RANK(I11,$I$1:$I$60) -> 50 | K11: =RAND() -> 0.016388862 | L11: =RANK(K11,$K$1:$K$120) -> 117 | M11: =RAND() -> 0.64925028 | N11: =RANK(M11,$M$1:$M$100) -> 45 | O11: =RAND() -> 0.16031843 | P11: =RANK(O11,$A$1:$A$80) -> #N/A | Q11: =RAND() -> 0.55497086 | R11: =RANK(Q11,$C$1:$C$160) -> #N/A | S11: =RAND() -> 0.9198357 | T11: =RANK(S11,$E$1:$E$20) -> #N/A | U11: =RAND() -> 0.24588075 | V11: =RANK(U11,$G$1:$G$40) -> #N/A | W11: =RAND() -> 0.89655949 | X11: =RANK(W11,$I$1:$I$60) -> #N/A | Y11: =RAND() -> 0.94519592 | Z11: =RANK(Y11,$K$1:$K$120) -> #N/A | AA11: =RAND() -> 0.22410496 | AB11: =RANK(AA11,$M$1:$M$100) -> #N/A
A12: =RAND() -> 0.1893981 | B12: =RANK(A12,$A$1:$A$80) -> 66 | C12: =RAND() -> 0.54693799 | D12: =RANK(C12,$C$1:$C$160) -> 76 | E12: =RAND() -> 0.10997721 | F12: =RANK(E12,$E$1:$E$20) -> 19 | G12: =RAND() -> 0.23897179 | H12: =RANK(G12,$G$1:$G$40) -> 31 | I12: =RAND() -> 0.90118435 | J12: =RANK(I12,$I$1:$I$60) -> 3 | K12: =RAND() -> 0.27380047 | L12: =RANK(K12,$K$1:$K$120) -> 85 | M12: =RAND() -> 0.92155294 | N12: =RANK(M12,$M$1:$M$100) -> 8 | O12: =RAND() -> 0.53229694 | P12: =RANK(O12,$A$1:$A$80) -> #N/A | Q12: =RAND() -> 0.91557785 | R12: =RANK(Q12,$C$1:$C$160) -> #N/A | S12: =RAND() -> 0.017412569 | T12: =RANK(S12,$E$1:$E$20) -> #N/A | U12: =RAND() -> 0.070451337 | V12: =RANK(U12,$G$1:$G$40) -> #N/A | W12: =RAND() -> 0.62505422 | X12: =RANK(W12,$I$1:$I$60) -> #N/A | Y12: =RAND() -> 0.90763591 | Z12: =RANK(Y12,$K$1:$K$120) -> #N/A | AA12: =RAND() -> 0.87678349 | AB12: =RANK(AA12,$M$1:$M$100) -> #N/A
A13: =RAND() -> 0.025873949 | B13: =RANK(A13,$A$1:$A$80) -> 79 | C13: =RAND() -> 0.093366276 | D13: =RANK(C13,$C$1:$C$160) -> 143 | E13: =RAND() -> 0.062945133 | F13: =RANK(E13,$E$1:$E$20) -> 20 | G13: =RAND() -> 0.14910291 | H13: =RANK(G13,$G$1:$G$40) -> 35 | I13: =RAND() -> 0.53314374 | J13: =RANK(I13,$I$1:$I$60) -> 23 | K13: =RAND() -> 0.60475343 | L13: =RANK(K13,$K$1:$K$120) -> 47 | M13: =RAND() -> 0.5844466 | N13: =RANK(M13,$M$1:$M$100) -> 49 | O13: =RAND() -> 0.3896038 | P13: =RANK(O13,$A$1:$A$80) -> #N/A | Q13: =RAND() -> 0.35398602 | R13: =RANK(Q13,$C$1:$C$160) -> #N/A | S13: =RAND() -> 0.74110859 | T13: =RANK(S13,$E$1:$E$20) -> #N/A | U13: =RAND() -> 0.56629933 | V13: =RANK(U13,$G$1:$G$40) -> #N/A | W13: =RAND() -> 0.16098924 | X13: =RANK(W13,$I$1:$I$60) -> #N/A | Y13: =RAND() -> 0.70945601 | Z13: =RANK(Y13,$K$1:$K$120) -> #N/A | AA13: =RAND() -> 0.89128446 | AB13: =RANK(AA13,$M$1:$M$100) -> #N/A
A14: =RAND() -> 0.4570872 | B14: =RANK(A14,$A$1:$A$80) -> 45 | C14: =RAND() -> 0.91676214 | D14: =RANK(C14,$C$1:$C$160) -> 14 | E14: =RAND() -> 0.62004322 | F14: =RANK(E14,$E$1:$E$20) -> 7 | G14: =RAND() -> 0.82619831 | H14: =RANK(G14,$G$1:$G$40) -> 9 | I14: =RAND() -> 0.55650023 | J14: =RANK(I14,$I$1:$I$60) -> 21 | K14: =RAND() -> 0.44631104 | L14: =RANK(K14,$K$1:$K$120) -> 65 | M14: =RAND() -> 0.1272497 | N14: =RANK(M14,$M$1:$M$100) -> 93 | O14: =RAND() -> 0.7244949 | P14: =RANK(O14,$A$1:$A$80) -> #N/A | Q14: =RAND() -> 0.031469773 | R14: =RANK(Q14,$C$1:$C$160) -> #N/A | S14: =RAND() -> 0.10321483 | T14: =RANK(S14,$E$1:$E$20) -> #N/A | U14: =RAND() -> 0.41196199 | V14: =RANK(U14,$G$1:$G$40) -> #N/A | W14: =RAND() -> 0.01738361 | X14: =RANK(W14,$I$1:$I$60) -> #N/A | Y14: =RAND() -> 0.033648198 | Z14: =RANK(Y14,$K$1:$K$120) -> #N/A | AA14: =RAND() -> 0.43388795 | AB14: =RANK(AA14,$M$1:$M$100) -> #N/A
... A20: =RAND() -> 0.20312751 | B20: =RANK(A20,$A$1:$A$80) -> 64 | C20: =RAND() -> 0.75050361 | D20: =RANK(C20,$C$1:$C$160) -> 43 | E20: =RAND() -> 0.32715832 | F20: =RANK(E20,$E$1:$E$20) -> 13 | G20: =RAND() -> 0.55267911 | H20: =RANK(G20,$G$1:$G$40) -> 20 | I20: =RAND() -> 0.31397829 | J20: =RANK(I20,$I$1:$I$60) -> 38 | K20: =RAND() -> 0.57896327 | L20: =RANK(K20,$K$1:$K$120) -> 50 | M20: =RAND() -> 0.22668434 | N20: =RANK(M20,$M$1:$M$100) -> 87 | O20: =RAND() -> 0.9012145 | P20: =RANK(O20,$A$1:$A$80) -> #N/A | Q20: =RAND() -> 0.81710677 | R20: =RANK(Q20,$C$1:$C$160) -> #N/A | S20: =RAND() -> 0.14273899 | T20: =RANK(S20,$E$1:$E$20) -> #N/A | U20: =RAND() -> 0.38865088 | V20: =RANK(U20,$G$1:$G$40) -> #N/A | W20: =RAND() -> 0.41062273 | X20: =RANK(W20,$I$1:$I$60) -> #N/A | Y20: =RAND() -> 0.4529515 | Z20: =RANK(Y20,$K$1:$K$120) -> #N/A | AA20: =RAND() -> 0.17580194 | AB20: =RANK(AA20,$M$1:$M$100) -> #N/A
A21: =RAND() -> 0.27864165 | B21: =RANK(A21,$A$1:$A$80) -> 59 | C21: =RAND() -> 0.28363883 | D21: =RANK(C21,$C$1:$C$160) -> 118 | G21: =RAND() -> 0.82090966 | H21: =RANK(G21,$G$1:$G$40) -> 10 | I21: =RAND() -> 0.33462915 | J21: =RANK(I21,$I$1:$I$60) -> 37 | K21: =RAND() -> 0.27745368 | L21: =RANK(K21,$K$1:$K$120) -> 84 | M21: =RAND() -> 0.29615649 | N21: =RANK(M21,$M$1:$M$100) -> 72 | O21: =RAND() -> 0.53234687 | P21: =RANK(O21,$A$1:$A$80) -> #N/A | Q21: =RAND() -> 0.15525355 | R21: =RANK(Q21,$C$1:$C$160) -> #N/A | S21: =RAND() -> 0.36936902 | T21: =RANK(S21,$E$1:$E$20) -> #N/A | U21: =RAND() -> 0.69410937 | V21: =RANK(U21,$G$1:$G$40) -> #N/A | W21: =RAND() -> 0.085739171 | X21: =RANK(W21,$I$1:$I$60) -> #N/A | Y21: =RAND() -> 0.92000341 | Z21: =RANK(Y21,$K$1:$K$120) -> #N/A | AA21: =RAND() -> 0.49113111 | AB21: =RANK(AA21,$M$1:$M$100) -> #N/A
A22: =RAND() -> 0.55221637 | B22: =RANK(A22,$A$1:$A$80) -> 36 | C22: =RAND() -> 0.50918691 | D22: =RANK(C22,$C$1:$C$160) -> 82 | G22: =RAND() -> 0.88978474 | H22: =RANK(G22,$G$1:$G$40) -> 3 | I22: =RAND() -> 0.17172703 | J22: =RANK(I22,$I$1:$I$60) -> 47 | K22: =RAND() -> 0.39135686 | L22: =RANK(K22,$K$1:$K$120) -> 71 | M22: =RAND() -> 0.078590194 | N22: =RANK(M22,$M$1:$M$100) -> 97 | O22: =RAND() -> 0.15374279 | P22: =RANK(O22,$A$1:$A$80) -> #N/A | Q22: =RAND() -> 0.76714672 | R22: =RANK(Q22,$C$1:$C$160) -> #N/A | U22: =RAND() -> 0.12064017 | V22: =RANK(U22,$G$1:$G$40) -> #N/A | W22: =RAND() -> 0.10974685 | X22: =RANK(W22,$I$1:$I$60) -> #N/A | Y22: =RAND() -> 0.92150455 | Z22: =RANK(Y22,$K$1:$K$120) -> #N/A | AA22: =RAND() -> 0.50883968 | AB22: =RANK(AA22,$M$1:$M$100) -> #N/A
A23: =RAND() -> 0.70120978 | B23: =RANK(A23,$A$1:$A$80) -> 22 | C23: =RAND() -> 0.78858455 | D23: =RANK(C23,$C$1:$C$160) -> 38 | G23: =RAND() -> 0.71990091 | H23: =RANK(G23,$G$1:$G$40) -> 14 | I23: =RAND() -> 0.26893371 | J23: =RANK(I23,$I$1:$I$60) -> 42 | K23: =RAND() -> 0.79145131 | L23: =RANK(K23,$K$1:$K$120) -> 23 | M23: =RAND() -> 0.99112459 | N23: =RANK(M23,$M$1:$M$100) -> 1 | O23: =RAND() -> 0.26452318 | P23: =RANK(O23,$A$1:$A$80) -> #N/A | Q23: =RAND() -> 0.81971678 | R23: =RANK(Q23,$C$1:$C$160) -> #N/A | U23: =RAND() -> 0.62277938 | V23: =RANK(U23,$G$1:$G$40) -> #N/A | W23: =RAND() -> 0.15861695 | X23: =RANK(W23,$I$1:$I$60) -> #N/A | Y23: =RAND() -> 0.058046073 | Z23: =RANK(Y23,$K$1:$K$120) -> #N/A | AA23: =RAND() -> 0.56825074 | AB23: =RANK(AA23,$M$1:$M$100) -> #N/A
A24: =RAND() -> 0.27740841 | B24: =RANK(A24,$A$1:$A$80) -> 60 | C24: =RAND() -> 0.39472838 | D24: =RANK(C24,$C$1:$C$160) -> 97 | G24: =RAND() -> 0.50441341 | H24: =RANK(G24,$G$1:$G$40) -> 24 | I24: =RAND() -> 0.64706585 | J24: =RANK(I24,$I$1:$I$60) -> 15 | K24: =RAND() -> 0.99217136 | L24: =RANK(K24,$K$1:$K$120) -> 4 | M24: =RAND() -> 0.2780733 | N24: =RANK(M24,$M$1:$M$100) -> 73 | O24: =RAND() -> 0.59673598 | P24: =RANK(O24,$A$1:$A$80) -> #N/A | Q24: =RAND() -> 0.49923803 | R24: =RANK(Q24,$C$1:$C$160) -> #N/A | U24: =RAND() -> 0.38609315 | V24: =RANK(U24,$G$1:$G$40) -> #N/A | W24: =RAND() -> 0.54222672 | X24: =RANK(W24,$I$1:$I$60) -> #N/A | Y24: =RAND() -> 0.065937425 | Z24: =RANK(Y24,$K$1:$K$120) -> #N/A | AA24: =RAND() -> 0.68058816 | AB24: =RANK(AA24,$M$1:$M$100) -> #N/A
A25: =RAND() -> 0.54234561 | B25: =RANK(A25,$A$1:$A$80) -> 38 | C25: =RAND() -> 0.21725134 | D25: =RANK(C25,$C$1:$C$160) -> 127 | G25: =RAND() -> 0.079996586 | H25: =RANK(G25,$G$1:$G$40) -> 38 | I25: =RAND() -> 0.24043327 | J25: =RANK(I25,$I$1:$I$60) -> 45 | K25: =RAND() -> 0.89180404 | L25: =RANK(K25,$K$1:$K$120) -> 14 | M25: =RAND() -> 0.89331467 | N25: =RANK(M25,$M$1:$M$100) -> 13 | O25: =RAND() -> 0.52764109 | P25: =RANK(O25,$A$1:$A$80) -> #N/A | Q25: =RAND() -> 0.65022115 | R25: =RANK(Q25,$C$1:$C$160) -> #N/A | U25: =RAND() -> 0.88390868 | V25: =RANK(U25,$G$1:$G$40) -> #N/A | W25: =RAND() -> 0.40745648 | X25: =RANK(W25,$I$1:$I$60) -> #N/A | Y25: =RAND() -> 0.11285992 | Z25: =RANK(Y25,$K$1:$K$120) -> #N/A | AA25: =RAND() -> 0.36784348 | AB25: =RANK(AA25,$M$1:$M$100) -> #N/A
A26: =RAND() -> 0.61256436 | B26: =RANK(A26,$A$1:$A$80) -> 29 | C26: =RAND() -> 0.49362329 | D26: =RANK(C26,$C$1:$C$160) -> 83 | G26: =RAND() -> 0.73365724 | H26: =RANK(G26,$G$1:$G$40) -> 13 | I26: =RAND() -> 0.41023208 | J26: =RANK(I26,$I$1:$I$60) -> 35 | K26: =RAND() -> 0.21188076 | L26: =RANK(K26,$K$1:$K$120) -> 94 | M26: =RAND() -> 0.98262474 | N26: =RANK(M26,$M$1:$M$100) -> 4 | O26: =RAND() -> 0.21277084 | P26: =RANK(O26,$A$1:$A$80) -> #N/A | Q26: =RAND() -> 0.35596145 | R26: =RANK(Q26,$C$1:$C$160) -> #N/A | U26: =RAND() -> 0.04682972 | V26: =RANK(U26,$G$1:$G$40) -> #N/A | W26: =RAND() -> 0.14042245 | X26: =RANK(W26,$I$1:$I$60) -> #N/A | Y26: =RAND() -> 0.10354914 | Z26: =RANK(Y26,$K$1:$K$120) -> #N/A | AA26: =RAND() -> 0.65891633 | AB26: =RANK(AA26,$M$1:$M$100) -> #N/A
A27: =RAND() -> 0.67787481 | B27: =RANK(A27,$A$1:$A$80) -> 23 | C27: =RAND() -> 0.87175846 | D27: =RANK(C27,$C$1:$C$160) -> 21 | G27: =RAND() -> 0.95178789 | H27: =RANK(G27,$G$1:$G$40) -> 1 | I27: =RAND() -> 0.021710848 | J27: =RANK(I27,$I$1:$I$60) -> 59 | K27: =RAND() -> 0.83050425 | L27: =RANK(K27,$K$1:$K$120) -> 19 | M27: =RAND() -> 0.90993252 | N27: =RANK(M27,$M$1:$M$100) -> 11 | O27: =RAND() -> 0.55086007 | P27: =RANK(O27,$A$1:$A$80) -> #N/A | Q27: =RAND() -> 0.060885821 | R27: =RANK(Q27,$C$1:$C$160) -> #N/A | U27: =RAND() -> 0.62282723 | V27: =RANK(U27,$G$1:$G$40) -> #N/A | W27: =RAND() -> 0.52076619 | X27: =RANK(W27,$I$1:$I$60) -> #N/A | Y27: =RAND() -> 0.51267522 | Z27: =RANK(Y27,$K$1:$K$120) -> #N/A | AA27: =RAND() -> 0.38978871 | AB27: =RANK(AA27,$M$1:$M$100) -> #N/A
A28: =RAND() -> 0.037644356 | B28: =RANK(A28,$A$1:$A$80) -> 77 | C28: =RAND() -> 0.16181515 | D28: =RANK(C28,$C$1:$C$160) -> 134 | G28: =RAND() -> 0.32189435 | H28: =RANK(G28,$G$1:$G$40) -> 27 | I28: =RAND() -> 0.52818326 | J28: =RANK(I28,$I$1:$I$60) -> 24 | K28: =RAND() -> 0.95939251 | L28: =RANK(K28,$K$1:$K$120) -> 6 | M28: =RAND() -> 0.74753897 | N28: =RANK(M28,$M$1:$M$100) -> 34 | O28: =RAND() -> 0.29441368 | P28: =RANK(O28,$A$1:$A$80) -> #N/A | Q28: =RAND() -> 0.36076139 | R28: =RANK(Q28,$C$1:$C$160) -> #N/A | U28: =RAND() -> 0.18560272 | V28: =RANK(U28,$G$1:$G$40) -> #N/A | W28: =RAND() -> 0.96717216 | X28: =RANK(W28,$I$1:$I$60) -> #N/A | Y28: =RAND() -> 0.70951762 | Z28: =RANK(Y28,$K$1:$K$120) -> #N/A | AA28: =RAND() -> 0.43865556 | AB28: =RANK(AA28,$M$1:$M$100) -> #N/A
A29: =RAND() -> 0.038983661 | B29: =RANK(A29,$A$1:$A$80) -> 76 | C29: =RAND() -> 0.068634079 | D29: =RANK(C29,$C$1:$C$160) -> 151 | G29: =RAND() -> 0.82807215 | H29: =RANK(G29,$G$1:$G$40) -> 8 | I29: =RAND() -> 0.037048365 | J29: =RANK(I29,$I$1:$I$60) -> 58 | K29: =RAND() -> 0.63994223 | L29: =RANK(K29,$K$1:$K$120) -> 40 | M29: =RAND() -> 0.7011093 | N29: =RANK(M29,$M$1:$M$100) -> 42 | O29: =RAND() -> 0.33626765 | P29: =RANK(O29,$A$1:$A$80) -> #N/A | Q29: =RAND() -> 0.75909619 | R29: =RANK(Q29,$C$1:$C$160) -> #N/A | U29: =RAND() -> 0.51359701 | V29: =RANK(U29,$G$1:$G$40) -> #N/A | W29: =RAND() -> 0.14513001 | X29: =RANK(W29,$I$1:$I$60) -> #N/A | Y29: =RAND() -> 0.17065862 | Z29: =RANK(Y29,$K$1:$K$120) -> #N/A | AA29: =RAND() -> 0.39091687 | AB29: =RANK(AA29,$M$1:$M$100) -> #N/A
A30: =RAND() -> 0.06497921 | B30: =RANK(A30,$A$1:$A$80) -> 74 | C30: =RAND() -> 0.76089392 | D30: =RANK(C30,$C$1:$C$160) -> 40 | G30: =RAND() -> 0.53230154 | H30: =RANK(G30,$G$1:$G$40) -> 22 | I30: =RAND() -> 0.43949344 | J30: =RANK(I30,$I$1:$I$60) -> 32 | K30: =RAND() -> 0.64288213 | L30: =RANK(K30,$K$1:$K$120) -> 37 | M30: =RAND() -> 0.8266732 | N30: =RANK(M30,$M$1:$M$100) -> 22 | O30: =RAND() -> 0.25431614 | P30: =RANK(O30,$A$1:$A$80) -> #N/A | Q30: =RAND() -> 0.12425459 | R30: =RANK(Q30,$C$1:$C$160) -> #N/A | U30: =RAND() -> 0.52185476 | V30: =RANK(U30,$G$1:$G$40) -> #N/A | W30: =RAND() -> 0.88042856 | X30: =RANK(W30,$I$1:$I$60) -> #N/A | Y30: =RAND() -> 0.82553744 | Z30: =RANK(Y30,$K$1:$K$120) -> #N/A | AA30: =RAND() -> 0.48977929 | AB30: =RANK(AA30,$M$1:$M$100) -> #N/A
A31: =RAND() -> 0.89058004 | B31: =RANK(A31,$A$1:$A$80) -> 7 | C31: =RAND() -> 0.72255776 | D31: =RANK(C31,$C$1:$C$160) -> 47 | G31: =RAND() -> 0.87729512 | H31: =RANK(G31,$G$1:$G$40) -> 6 | I31: =RAND() -> 0.38813933 | J31: =RANK(I31,$I$1:$I$60) -> 36 | K31: =RAND() -> 0.39737455 | L31: =RANK(K31,$K$1:$K$120) -> 69 | M31: =RAND() -> 0.56873387 | N31: =RANK(M31,$M$1:$M$100) -> 51 | O31: =RAND() -> 0.38251365 | P31: =RANK(O31,$A$1:$A$80) -> #N/A | Q31: =RAND() -> 0.12610291 | R31: =RANK(Q31,$C$1:$C$160) -> #N/A | U31: =RAND() -> 0.48951353 | V31: =RANK(U31,$G$1:$G$40) -> #N/A | W31: =RAND() -> 0.54845558 | X31: =RANK(W31,$I$1:$I$60) -> #N/A | Y31: =RAND() -> 0.4430912 | Z31: =RANK(Y31,$K$1:$K$120) -> #N/A | AA31: =RAND() -> 0.46781274 | AB31: =RANK(AA31,$M$1:$M$100) -> #N/A
A32: =RAND() -> 0.92096745 | B32: =RANK(A32,$A$1:$A$80) -> 4 | C32: =RAND() -> 0.93127025 | D32: =RANK(C32,$C$1:$C$160) -> 12 | G32: =RAND() -> 0.80759366 | H32: =RANK(G32,$G$1:$G$40) -> 12 | I32: =RAND() -> 0.89092603 | J32: =RANK(I32,$I$1:$I$60) -> 4 | K32: =RAND() -> 0.70209984 | L32: =RANK(K32,$K$1:$K$120) -> 34 | M32: =RAND() -> 0.26065739 | N32: =RANK(M32,$M$1:$M$100) -> 80 | O32: =RAND() -> 0.038467839 | P32: =RANK(O32,$A$1:$A$80) -> #N/A | Q32: =RAND() -> 0.31830075 | R32: =RANK(Q32,$C$1:$C$160) -> #N/A | U32: =RAND() -> 0.05771374 | V32: =RANK(U32,$G$1:$G$40) -> #N/A | W32: =RAND() -> 0.80735622 | X32: =RANK(W32,$I$1:$I$60) -> #N/A | Y32: =RAND() -> 0.72625799 | Z32: =RANK(Y32,$K$1:$K$120) -> #N/A | AA32: =RAND() -> 0.72704562 | AB32: =RANK(AA32,$M$1:$M$100) -> #N/A
A33: =RAND() -> 0.7628741 | B33: =RANK(A33,$A$1:$A$80) -> 17 | C33: =RAND() -> 0.31424333 | D33: =RANK(C33,$C$1:$C$160) -> 113 | G33: =RAND() -> 0.21105367 | H33: =RANK(G33,$G$1:$G$40) -> 32 | I33: =RAND() -> 0.092676993 | J33: =RANK(I33,$I$1:$I$60) -> 52 | K33: =RAND() -> 0.90608999 | L33: =RANK(K33,$K$1:$K$120) -> 13 | M33: =RAND() -> 0.24511388 | N33: =RANK(M33,$M$1:$M$100) -> 83 | O33: =RAND() -> 0.41511976 | P33: =RANK(O33,$A$1:$A$80) -> #N/A | Q33: =RAND() -> 0.27750423 | R33: =RANK(Q33,$C$1:$C$160) -> #N/A | U33: =RAND() -> 0.92052063 | V33: =RANK(U33,$G$1:$G$40) -> #N/A | W33: =RAND() -> 0.25149267 | X33: =RANK(W33,$I$1:$I$60) -> #N/A | Y33: =RAND() -> 0.9117385 | Z33: =RANK(Y33,$K$1:$K$120) -> #N/A | AA33: =RAND() -> 0.44175923 | AB33: =RANK(AA33,$M$1:$M$100) -> #N/A
... A40: =RAND() -> 0.32490853 | B40: =RANK(A40,$A$1:$A$80) -> 55 | C40: =RAND() -> 0.59360781 | D40: =RANK(C40,$C$1:$C$160) -> 71 | G40: =RAND() -> 0.55065663 | H40: =RANK(G40,$G$1:$G$40) -> 21 | I40: =RAND() -> 0.88397124 | J40: =RANK(I40,$I$1:$I$60) -> 6 | K40: =RAND() -> 0.52087209 | L40: =RANK(K40,$K$1:$K$120) -> 55 | M40: =RAND() -> 0.57078307 | N40: =RANK(M40,$M$1:$M$100) -> 50 | O40: =RAND() -> 0.34368886 | P40: =RANK(O40,$A$1:$A$80) -> #N/A | Q40: =RAND() -> 0.87274723 | R40: =RANK(Q40,$C$1:$C$160) -> #N/A | U40: =RAND() -> 0.77292182 | V40: =RANK(U40,$G$1:$G$40) -> #N/A | W40: =RAND() -> 0.48629352 | X40: =RANK(W40,$I$1:$I$60) -> #N/A | Y40: =RAND() -> 0.50394535 | Z40: =RANK(Y40,$K$1:$K$120) -> #N/A | AA40: =RAND() -> 0.50173388 | AB40: =RANK(AA40,$M$1:$M$100) -> #N/A
A41: =RAND() -> 0.27064717 | B41: =RANK(A41,$A$1:$A$80) -> 62 | C41: =RAND() -> 0.024908953 | D41: =RANK(C41,$C$1:$C$160) -> 157 | I41: =RAND() -> 0.0095635988 | J41: =RANK(I41,$I$1:$I$60) -> 60 | K41: =RAND() -> 0.30682595 | L41: =RANK(K41,$K$1:$K$120) -> 83 | M41: =RAND() -> 0.98353204 | N41: =RANK(M41,$M$1:$M$100) -> 3 | O41: =RAND() -> 0.58501289 | P41: =RANK(O41,$A$1:$A$80) -> #N/A | Q41: =RAND() -> 0.96695337 | R41: =RANK(Q41,$C$1:$C$160) -> #N/A | U41: =RAND() -> 0.69448358 | V41: =RANK(U41,$G$1:$G$40) -> #N/A | W41: =RAND() -> 0.64411162 | X41: =RANK(W41,$I$1:$I$60) -> #N/A | Y41: =RAND() -> 0.12887615 | Z41: =RANK(Y41,$K$1:$K$120) -> #N/A | AA41: =RAND() -> 0.73246813 | AB41: =RANK(AA41,$M$1:$M$100) -> #N/A
A42: =RAND() -> 0.35648268 | B42: =RANK(A42,$A$1:$A$80) -> 50 | C42: =RAND() -> 0.38932319 | D42: =RANK(C42,$C$1:$C$160) -> 98 | I42: =RAND() -> 0.037756898 | J42: =RANK(I42,$I$1:$I$60) -> 57 | K42: =RAND() -> 0.1712691 | L42: =RANK(K42,$K$1:$K$120) -> 99 | M42: =RAND() -> 0.72803525 | N42: =RANK(M42,$M$1:$M$100) -> 40 | O42: =RAND() -> 0.99537761 | P42: =RANK(O42,$A$1:$A$80) -> #N/A | Q42: =RAND() -> 0.78112798 | R42: =RANK(Q42,$C$1:$C$160) -> #N/A | W42: =RAND() -> 0.8008615 | X42: =RANK(W42,$I$1:$I$60) -> #N/A | Y42: =RAND() -> 0.53312712 | Z42: =RANK(Y42,$K$1:$K$120) -> #N/A | AA42: =RAND() -> 0.54809098 | AB42: =RANK(AA42,$M$1:$M$100) -> #N/A
A43: =RAND() -> 0.60583323 | B43: =RANK(A43,$A$1:$A$80) -> 30 | C43: =RAND() -> 0.35304031 | D43: =RANK(C43,$C$1:$C$160) -> 107 | I43: =RAND() -> 0.52624838 | J43: =RANK(I43,$I$1:$I$60) -> 25 | K43: =RAND() -> 0.99558522 | L43: =RANK(K43,$K$1:$K$120) -> 2 | M43: =RAND() -> 0.41643234 | N43: =RANK(M43,$M$1:$M$100) -> 61 | O43: =RAND() -> 0.86627438 | P43: =RANK(O43,$A$1:$A$80) -> #N/A | Q43: =RAND() -> 0.19166544 | R43: =RANK(Q43,$C$1:$C$160) -> #N/A | W43: =RAND() -> 0.96605225 | X43: =RANK(W43,$I$1:$I$60) -> #N/A | Y43: =RAND() -> 0.28072921 | Z43: =RANK(Y43,$K$1:$K$120) -> #N/A | AA43: =RAND() -> 0.48765099 | AB43: =RANK(AA43,$M$1:$M$100) -> #N/A
A44: =RAND() -> 0.29755727 | B44: =RANK(A44,$A$1:$A$80) -> 56 | C44: =RAND() -> 0.64140685 | D44: =RANK(C44,$C$1:$C$160) -> 59 | I44: =RAND() -> 0.64369787 | J44: =RANK(I44,$I$1:$I$60) -> 16 | K44: =RAND() -> 0.48498802 | L44: =RANK(K44,$K$1:$K$120) -> 60 | M44: =RAND() -> 0.7975951 | N44: =RANK(M44,$M$1:$M$100) -> 27 | O44: =RAND() -> 0.58470488 | P44: =RANK(O44,$A$1:$A$80) -> #N/A | Q44: =RAND() -> 0.50418362 | R44: =RANK(Q44,$C$1:$C$160) -> #N/A | W44: =RAND() -> 0.99178942 | X44: =RANK(W44,$I$1:$I$60) -> #N/A | Y44: =RAND() -> 0.40778502 | Z44: =RANK(Y44,$K$1:$K$120) -> #N/A | AA44: =RAND() -> 0.87192822 | AB44: =RANK(AA44,$M$1:$M$100) -> #N/A
A45: =RAND() -> 0.27348307 | B45: =RANK(A45,$A$1:$A$80) -> 61 | C45: =RAND() -> 0.75906734 | D45: =RANK(C45,$C$1:$C$160) -> 41 | I45: =RAND() -> 0.25345406 | J45: =RANK(I45,$I$1:$I$60) -> 44 | K45: =RAND() -> 0.2715843 | L45: =RANK(K45,$K$1:$K$120) -> 86 | M45: =RAND() -> 0.3208831 | N45: =RANK(M45,$M$1:$M$100) -> 70 | O45: =RAND() -> 0.69212419 | P45: =RANK(O45,$A$1:$A$80) -> #N/A | Q45: =RAND() -> 0.39227165 | R45: =RANK(Q45,$C$1:$C$160) -> #N/A | W45: =RAND() -> 0.90983645 | X45: =RANK(W45,$I$1:$I$60) -> #N/A | Y45: =RAND() -> 0.96127706 | Z45: =RANK(Y45,$K$1:$K$120) -> #N/A | AA45: =RAND() -> 0.25847537 | AB45: =RANK(AA45,$M$1:$M$100) -> #N/A
A46: =RAND() -> 0.40741313 | B46: =RANK(A46,$A$1:$A$80) -> 48 | C46: =RAND() -> 0.96686341 | D46: =RANK(C46,$C$1:$C$160) -> 4 | I46: =RAND() -> 0.65886693 | J46: =RANK(I46,$I$1:$I$60) -> 13 | K46: =RAND() -> 0.14771409 | L46: =RANK(K46,$K$1:$K$120) -> 102 | M46: =RAND() -> 0.83733665 | N46: =RANK(M46,$M$1:$M$100) -> 21 | O46: =RAND() -> 0.069649793 | P46: =RANK(O46,$A$1:$A$80) -> #N/A | Q46: =RAND() -> 0.55191436 | R46: =RANK(Q46,$C$1:$C$160) -> #N/A | W46: =RAND() -> 0.89636183 | X46: =RANK(W46,$I$1:$I$60) -> #N/A | Y46: =RAND() -> 0.10778046 | Z46: =RANK(Y46,$K$1:$K$120) -> #N/A | AA46: =RAND() -> 0.093559577 | AB46: =RANK(AA46,$M$1:$M$100) -> #N/A
A47: =RAND() -> 0.085041974 | B47: =RANK(A47,$A$1:$A$80) -> 73 | C47: =RAND() -> 0.63745779 | D47: =RANK(C47,$C$1:$C$160) -> 60 | I47: =RAND() -> 0.29819422 | J47: =RANK(I47,$I$1:$I$60) -> 39 | K47: =RAND() -> 0.63768781 | L47: =RANK(K47,$K$1:$K$120) -> 43 | M47: =RAND() -> 0.87832791 | N47: =RANK(M47,$M$1:$M$100) -> 15 | O47: =RAND() -> 0.32279731 | P47: =RANK(O47,$A$1:$A$80) -> #N/A | Q47: =RAND() -> 0.39600853 | R47: =RANK(Q47,$C$1:$C$160) -> #N/A | W47: =RAND() -> 0.6944053 | X47: =RANK(W47,$I$1:$I$60) -> #N/A | Y47: =RAND() -> 0.10225037 | Z47: =RANK(Y47,$K$1:$K$120) -> #N/A | AA47: =RAND() -> 0.35423484 | AB47: =RANK(AA47,$M$1:$M$100) -> #N/A
A48: =RAND() -> 0.039299991 | B48: =RANK(A48,$A$1:$A$80) -> 75 | C48: =RAND() -> 0.1211375 | D48: =RANK(C48,$C$1:$C$160) -> 136 | I48: =RAND() -> 0.14375334 | J48: =RANK(I48,$I$1:$I$60) -> 49 | K48: =RAND() -> 0.88688267 | L48: =RANK(K48,$K$1:$K$120) -> 15 | M48: =RAND() -> 0.75565903 | N48: =RANK(M48,$M$1:$M$100) -> 32 | O48: =RAND() -> 0.22661292 | P48: =RANK(O48,$A$1:$A$80) -> #N/A | Q48: =RAND() -> 0.47955575 | R48: =RANK(Q48,$C$1:$C$160) -> #N/A | W48: =RAND() -> 0.38610178 | X48: =RANK(W48,$I$1:$I$60) -> #N/A | Y48: =RAND() -> 0.89118132 | Z48: =RANK(Y48,$K$1:$K$120) -> #N/A | AA48: =RAND() -> 0.2783691 | AB48: =RANK(AA48,$M$1:$M$100) -> #N/A
A49: =RAND() -> 0.60077247 | B49: =RANK(A49,$A$1:$A$80) -> 31 | C49: =RAND() -> 0.8812537 | D49: =RANK(C49,$C$1:$C$160) -> 20 | I49: =RAND() -> 0.51046742 | J49: =RANK(I49,$I$1:$I$60) -> 27 | K49: =RAND() -> 0.4873059 | L49: =RANK(K49,$K$1:$K$120) -> 59 | M49: =RAND() -> 0.64770403 | N49: =RANK(M49,$M$1:$M$100) -> 46 | O49: =RAND() -> 0.66475018 | P49: =RANK(O49,$A$1:$A$80) -> #N/A | Q49: =RAND() -> 0.77577743 | R49: =RANK(Q49,$C$1:$C$160) -> #N/A | W49: =RAND() -> 0.4465993 | X49: =RANK(W49,$I$1:$I$60) -> #N/A | Y49: =RAND() -> 0.50984373 | Z49: =RANK(Y49,$K$1:$K$120) -> #N/A | AA49: =RAND() -> 0.20202157 | AB49: =RANK(AA49,$M$1:$M$100) -> #N/A
A50: =RAND() -> 0.35547993 | B50: =RANK(A50,$A$1:$A$80) -> 51 | C50: =RAND() -> 0.38086138 | D50: =RANK(C50,$C$1:$C$160) -> 100 | I50: =RAND() -> 0.14765008 | J50: =RANK(I50,$I$1:$I$60) -> 48 | K50: =RAND() -> 0.93720893 | L50: =RANK(K50,$K$1:$K$120) -> 9 | M50: =RAND() -> 0.34914644 | N50: =RANK(M50,$M$1:$M$100) -> 68 | O50: =RAND() -> 0.025347462 | P50: =RANK(O50,$A$1:$A$80) -> #N/A | Q50: =RAND() -> 0.31797777 | R50: =RANK(Q50,$C$1:$C$160) -> #N/A | W50: =RAND() -> 0.87343337 | X50: =RANK(W50,$I$1:$I$60) -> #N/A | Y50: =RAND() -> 0.69631387 | Z50: =RANK(Y50,$K$1:$K$120) -> #N/A | AA50: =RAND() -> 0.62735323 | AB50: =RANK(AA50,$M$1:$M$100) -> #N/A
A51: =RAND() -> 0.52331937 | B51: =RANK(A51,$A$1:$A$80) -> 40 | C51: =RAND() -> 0.45739516 | D51: =RANK(C51,$C$1:$C$160) -> 88 | I51: =RAND() -> 0.90535444 | J51: =RANK(I51,$I$1:$I$60) -> 2 | K51: =RAND() -> 0.41866941 | L51: =RANK(K51,$K$1:$K$120) -> 66 | M51: =RAND() -> 0.23155034 | N51: =RANK(M51,$M$1:$M$100) -> 85 | O51: =RAND() -> 0.71829334 | P51: =RANK(O51,$A$1:$A$80) -> #N/A | Q51: =RAND() -> 0.36989924 | R51: =RANK(Q51,$C$1:$C$160) -> #N/A | W51: =RAND() -> 0.045047489 | X51: =RANK(W51,$I$1:$I$60) -> #N/A | Y51: =RAND() -> 0.16433289 | Z51: =RANK(Y51,$K$1:$K$120) -> #N/A | AA51: =RAND() -> 0.33152417 | AB51: =RANK(AA51,$M$1:$M$100) -> #N/A
...
